Workbook

Sheet VIGÊNCIA MAIO 2021
A1: GRAND MESSEJANA II - VIGÊNCIA MAIO 2021
A2: NOME | B2: APTO | C2: ALUGUEL | D2: DESCONTO | E2: ALUGUEL C/ DESCONTO | F2: GARAGEM | G2: IPTU | H2: SEG INC. | I2: TOTAL | J2: COMISSÃO | K2: REPASSE | L2: OBSERVAÇÃO | M2: VENC. | N2: CARÊNCIA
B3: 1
B4: 2
B5: 3
B6: 4
B7: 5
B8: 6
B9: 7
B10: 8
B11: 9
A12: JOÃO CARLOS | B12: 10 | C12: 600 | D12: =10%*C12 -> 60 | E12: =C12-D12 -> 540 | F12: 0 | G12: =B52 -> 8.5683215 | H12: 0 | I12: =SUM(E12:H12) -> 548.56832 | J12: =I12*7% -> 38.399783 | K12: =I12-J12 -> 510.16854 | L12: DESCONTO 10% (1/12). IPTU (1/1). SEGURO SERÁ COBRADO A PARTIR DE JUNHO. | M12: 10 | N12: 11
B13: 11
B14: 12
B15: 13
B16: 15
B17: 15
B18: 16
B19: 17
B20: 18
B21: 19
B22: 20
B23: 21
B24: 22
... B26: 24
A27: SHIRLEY | B27: 25 | C27: =704/31*3 -> 68.129032 | D27: =10%*C27 -> 6.8129032 | E27: =C27-D27 -> 61.316129 | F27: =30/31*3 -> 2.9032258 | G27: =D82 -> 8.5683215 | H27: 0 | I27: =SUM(E27:H27) -> 72.787676 | J27: =7%*I27 -> 5.0951373 | K27: =I27-J27 -> 67.692539 | L27: ALUGUEL PROPORCIONAL DE 03 DIAS (29/05 A 31/05). DESCONTO 10% (1/12). IPTU (1/1). SEGURO SERÁ COBRADO A PARTIR DE JUNHO. | M27: 10 | N27: 11
B28: 26
A29: LUIZA | B29: 27 | C29: =650/31*18 -> 377.41935 | D29: =10%*C29 -> 37.741935 | E29: =C29-D29 -> 339.67742 | F29: =60/31*18 -> 34.83871 | G29: =D86 -> 8.5683215 | H29: =D85 -> 19.836667 | I29: =SUM(E29:H29) -> 402.92112 | J29: =7%*I29 -> 28.204478 | K29: =I29-J29 -> 374.71664 | L29: ALUGUEL PROPORCIONAL DE 18 DIAS (14/05 A 31/05). DESCONTO 10% (1/12). IPTU (1/1). SEGURO (1/6). | M29: 10 | N29: 11
A30: TOTAL | C30: =SUM(C3:C29) -> 1045.5484 | D30: =SUM(D3:D29) -> 104.55484 | E30: =SUM(E3:E29) -> 940.99355 | F30: =SUM(F3:F29) -> 37.741935 | G30: =SUM(G3:G29) -> 25.704965 | H30: =SUM(H3:H29) -> 19.836667 | I30: =SUM(I3:I29) -> 1024.2771 | J30: =SUM(J3:J29) -> 71.699398 | K30: =SUM(K3:K29) -> 952.57772
A32: OBSERVAÇÕES | L32: COMISSÃO ADMINISTRAÇÃO
A33: SEGURO 01 | L33: COMISSÃO 7% | N33: =J30 -> 71.699398
A34: IPTU 01
A35: SEGURO 02
A36: IPTU 02 | L36: OUTRAS COMISSÕES E DESPESAS
A37: SEGURO 03 | L37: SEGURO APTO 27 (1/6) | N37: =D85 -> 19.836667
A38: IPTU 03 | L38: 05 LIMPEZAS (01/05 - 08/05 - 15/05 - 22/05 - 29/05) | N38: =100*5 -> 500
A39: SEGURO 04
A40: IPTU 04
A41: SEGURO 05
A42: IPTU 05
...

Sheet VIGÊNCIA JUNHO 2021
A1: GRAND MESSEJANA II - VIGÊNCIA JUNHO 2021
A2: INTERMEDIAÇÃO DE MAIO
A3: NOME | B3: APTO | C3: ALUGUEL | D3: DESCONTO | E3: ALUGUEL C/ DESCONTO | F3: GARAGEM | G3: IPTU | H3: SEG INC. | I3: TOTAL | J3: COMISSÃO | K3: REPASSE | L3: OBSERVAÇÃO | M3: VENC. | N3: CARÊNCIA
A4: JOÃO CARLOS | B4: 10 | C4: 600 | D4: =10%*C4 -> 60 | E4: =C4-D4 -> 540 | F4: 0 | G4: 0 | H4: =D58 -> 17.825 | I4: =SUM(E4:H4) -> 557.825 | J4: =(C4+F4)*50% -> 300 | K4: =I4-J4 -> 257.825 | L4: DESCONTO 10% (2/12). SEGURO (1/6). | M4: 10 | N4: 11
A5: SHIRLEY | B5: 25 | C5: =704 -> 704 | D5: =10%*C5 -> 70.4 | E5: =C5-D5 -> 633.6 | F5: =30 -> 30 | G5: 0 | H5: =D88 -> 19.95 | I5: =SUM(E5:H5) -> 683.55 | J5: =(C5+F5)*50% -> 367 | K5: =I5-J5 -> 316.55 | L5: DESCONTO 10% (2/12). SEGURO (1/6). | M5: 10 | N5: 11
A6: LUIZA | B6: 27 | C6: =650 -> 650 | D6: =10%*C6 -> 65 | E6: =C6-D6 -> 585 | F6: =60 -> 60 | G6: 0 | H6: =D92 -> 19.836667 | I6: =SUM(E6:H6) -> 664.83667 | J6: =(C6+F6)*50% -> 355 | K6: =I6-J6 -> 309.83667 | L6: DESCONTO 10% (2/12). SEGURO (2/6). | M6: 10 | N6: 11
A7: TOTAL | C7: =SUM(C4:C6) -> 1954 | D7: =SUM(D4:D6) -> 195.4 | E7: =SUM(E4:E6) -> 1758.6 | F7: =SUM(F4:F6) -> 90 | G7: =SUM(G4:G6) -> 0 | H7: =SUM(H4:H6) -> 57.611667 | I7: =SUM(I4:I6) -> 1906.2117 | J7: =SUM(J4:J6) -> 1022 | K7: =SUM(K4:K6) -> 884.21167
A8: JUNHO DE 2021
A9: NOME | B9: APTO | C9: ALUGUEL | D9: DESCONTO | E9: ALUGUEL C/ DESCONTO | F9: GARAGEM | G9: IPTU | H9: SEG INC. | I9: TOTAL | J9: COMISSÃO | K9: REPASSE | L9: OBSERVAÇÃO | M9: VENC. | N9: CARÊNCIA
B10: 1
B11: 2
B12: 3
B13: 4
B14: 5
B15: 6
B16: 7
B17: 8
B18: 9
A19: JOÃO CARLOS | B19: 10 | L19: INTERMEDIAÇÃO
B20: 11
B21: 12
B22: 13
B23: 15
B24: 15
A25: VANESSA | B25: 16 | C25: ='GERAL 2021'!G18/30*13 -> 277.33333 | D25: =10%*C25 -> 27.733333 | E25: =C25-D25 -> 249.6 | F25: =60/30*13 -> 26 | G25: =D71 -> 7.4972813 | H25: =D70 -> 19.811667 | I25: =SUM(E25:H25) -> 302.90895 | J25: =I25*7% -> 21.203626 | K25: =I25-J25 -> 281.70532 | L25: ALUGUEL PROPORCIONAL DE 13 DIAS (18/06 A 30/06). DESCONTO 10% (1/12). IPTU (1/1). SEGURO (1/6). | M25: 10 | N25: 11
B26: 17
A27: FREDSON | B27: 18 | C27: ='GERAL 2021'!G20/30*24 -> 520 | D27: =10%*C27 -> 52 | E27: =C27-D27 -> 468 | F27: =30/30*24 -> 24 | G27: =D75 -> 7.4972813 | H27: =D74 -> 19.836667 | I27: =SUM(E27:H27) -> 519.33395 | J27: =I27*7% -> 36.353376 | K27: =I27-J27 -> 482.98057 | L27: ALUGUEL PROPORCIONAL DE 24 DIAS (07/06 A 30/06). DESCONTO 10% (1/12). IPTU (1/1). SEGURO (1/6). | M27: 10 | N27: 11
B28: 19
B29: 20
B30: 21
B31: 22
B32: 23
B33: 24
A34: SHIRLEY | B34: 25 | L34: INTERMEDIAÇÃO
B35: 26
A36: LUIZA | B36: 27 | L36: INTERMEDIAÇÃO
A37: TOTAL | C37: =SUM(C10:C36) -> 797.33333 | D37: =SUM(D10:D36) -> 79.733333 | E37: =SUM(E10:E36) -> 717.6 | F37: =SUM(F10:F36) -> 50 | G37: =SUM(G10:G36) -> 14.994563 | H37: =SUM(H10:H36) -> 39.648333 | I37: =SUM(I10:I36) -> 822.2429 | J37: =SUM(J10:J36) -> 57.557003 | K37: =SUM(K10:K36) -> 764.68589
A39: OBSERVAÇÕES | L39: COMISSÃO ADMINISTRAÇÃO
A40: SEGURO 01 | L40: COMISSÃO 7% | N40: =J37 -> 57.557003
A41: IPTU 01 | L41: INTERMEDIAÇÃO | N41: =J7 -> 1022
...

Sheet VIGÊNCIA JULHO 2021
A1: GRAND MESSEJANA II
A2: INTERMEDIAÇÃO DE JUNHO
A3: NOME | B3: APTO | C3: ALUGUEL | D3: DESCONTO | E3: ALUGUEL C/ DESCONTO | F3: GARAGEM | G3: IPTU | H3: SEG INC. | I3: TOTAL | J3: COMISSÃO | K3: REPASSE | L3: OBSERVAÇÃO | M3: VENC. | N3: CARÊNCIA
A4: VANESSA | B4: 16 | C4: ='GERAL 2021'!G18 -> 640 | D4: =10%*C4 -> 64 | E4: =C4-D4 -> 576 | F4: =60 -> 60 | G4: 0 | H4: =D69 -> 19.811667 | I4: =SUM(E4:H4) -> 655.81167 | J4: =60%*(C4+F4) -> 420 | K4: =I4-J4 -> 235.81167 | L4: DESCONTO 10% (2/12). SEGURO (2/6). | M4: 10 | N4: 11
A5: FREDSON | B5: 18 | C5: ='GERAL 2021'!G20 -> 650 | D5: =10%*C5 -> 65 | E5: =C5-D5 -> 585 | F5: =30 -> 30 | G5: 0 | H5: 19.9 | I5: =SUM(E5:H5) -> 634.9 | J5: =60%*(C5+F5) -> 408 | K5: =I5-J5 -> 226.9 | L5: DESCONTO 10% (2/12). SEGURO (2/6). | M5: 10 | N5: 11
A6: TOTAL | C6: =SUM(C4:C5) -> 1290 | D6: =SUM(D4:D5) -> 129 | E6: =SUM(E4:E5) -> 1161 | F6: =SUM(F4:F5) -> 90 | G6: =SUM(G4:G5) -> 0 | H6: =SUM(H4:H5) -> 39.711667 | I6: =SUM(I4:I5) -> 1290.7117 | J6: =SUM(J4:J5) -> 828 | K6: =SUM(K4:K5) -> 462.71167
A7: VIGÊNCIA DE JULHO DE 2021
A8: NOME | B8: APTO | C8: ALUGUEL | D8: DESCONTO | E8: ALUGUEL C/ DESCONTO | F8: GARAGEM | G8: IPTU | H8: SEG INC. | I8: TOTAL | J8: COMISSÃO | K8: REPASSE | L8: OBSERVAÇÃO | M8: VENC. | N8: CARÊNCIA
A9: JOÃO PAULO | B9: 1 | C9: =600/31*2 -> 38.709677 | D9: =C9*10% -> 3.8709677 | E9: =C9-D9 -> 34.83871 | F9: =50/31*2 -> 3.2258065 | G9: =D40 -> 6.4262411 | H9: 0 | I9: =SUM(E9:H9) -> 44.490757 | J9: =I9*7% -> 3.114353 | K9: =I9-J9 -> 41.376404 | L9: ALUGUEL E IPTU PROPORCIONAIS A 02 DIAS (30/07 A 31/07). DESCONTO 10% (1/12). IPTU (1/1). SEGURO SERÁ COBRADO A PARTIR DE AGOSTO. | M9: 10 | N9: 11
B10: 2
B11: 3
B12: 4
B13: 5
B14: 6
B15: 7
B16: 8
B17: 9
A18: JOÃO CARLOS | B18: 10 | C18: 600 | D18: =10%*C18 -> 60 | E18: =C18-D18 -> 540 | F18: 0 | G18: 0 | H18: =D57 -> 17.825 | I18: =SUM(E18:H18) -> 557.825 | J18: =I18*7% -> 39.04775 | K18: =I18-J18 -> 518.77725 | L18: DESCONTO 10% (3/12). SEGURO (2/6). | M18: 10 | N18: 11
B19: 11
B20: 12
B21: 13
B22: 15
B23: 15
A24: VANESSA | B24: 16 | C24: 0 | D24: =10%*C24 -> 0 | E24: =C24-D24 -> 0 | F24: 0 | G24: 0 | H24: 0 | I24: =SUM(E24:H24) -> 0 | J24: =I24*7% -> 0 | K24: =I24-J24 -> 0 | L24: INTERMEDIAÇÃO | M24: 10 | N24: 11
A25: MATEUS | B25: 17 | C25: ='GERAL 2021'!G19/31*20 -> 412.90323 | D25: =10%*C25 -> 41.290323 | E25: =(C25-D25) -> 371.6129 | F25: 0 | G25: =D72 -> 6.4262411 | H25: 19.82 | I25: =SUM(E25:H25) -> 397.85914 | J25: =I25*7% -> 27.85014 | K25: =I25-J25 -> 370.009 | L25: ALUGUEL E IPTU PROPORCIONAIS A 20 DIAS (12/07 A 31/07). DESCONTO 10% (1/12). IPTU (1/1). SEGURO (1/6).
A26: FREDSON | B26: 18 | C26: 0 | D26: =10%*C26 -> 0 | E26: =C26-D26 -> 0 | F26: 0 | G26: 0 | H26: 0 | I26: =SUM(E26:H26) -> 0 | J26: =I26*7% -> 0 | K26: =I26-J26 -> 0 | L26: INTERMEDIAÇÃO | M26: 10 | N26: 11
B27: 19
B28: 20
B29: 21
B30: 22
B31: 23
B32: 24
A33: SHIRLEY | B33: 25 | C33: =704 -> 704 | D33: =10%*C33 -> 70.4 | E33: =C33-D33 -> 633.6 | F33: =30 -> 30 | G33: 0 | H33: 19.99 | I33: =SUM(E33:H33) -> 683.59 | J33: =I33*7% -> 47.8513 | K33: =I33-J33 -> 635.7387 | L33: DESCONTO 10% (3/12). SEGURO (2/6). | M33: 10 | N33: 11
B34: 26
A35: LUIZA | B35: 27 | C35: =650 -> 650 | D35: =10%*C35 -> 65 | E35: =C35-D35 -> 585 | F35: =60 -> 60 | G35: 0 | H35: =D91 -> 19.836667 | I35: =SUM(E35:H35) -> 664.83667 | J35: =I35*7% -> 46.538567 | K35: =I35-J35 -> 618.2981 | L35: DESCONTO 10% (3/12). SEGURO (3/6). | M35: 10 | N35: 11
A36: TOTAL | C36: =SUM(C9:C35) -> 2405.6129 | D36: =SUM(D9:D35) -> 240.56129 | E36: =SUM(E9:E35) -> 2165.0516 | F36: =SUM(F9:F35) -> 93.225806 | G36: =SUM(G9:G35) -> 12.852482 | H36: =SUM(H9:H35) -> 77.471667 | I36: =SUM(I9:I35) -> 2348.6016 | J36: =SUM(J9:J35) -> 164.40211 | K36: =SUM(K9:K35) -> 2184.1995
A38: OBSERVAÇÕES | L38: COMISSÃO ADMINISTRAÇÃO
A39: SEGURO 01 | B39: ='GERAL 2021'!K3 -> 118.43 | C39: 6 | D39: =B39/C39 -> 19.738333 | L39: COMISSÃO 7% | N39: =J36 -> 164.40211
A40: IPTU 01 | B40: ='GERAL 2021'!I3 -> 1.0710402 | C40: 6 | D40: =B40*C40 -> 6.4262411 | L40: INTERMEDIAÇÃO | N40: =J6 -> 828
A41: SEGURO 02
...

Sheet VIGÊNCIA AGOSTO 2021
A1: GRAND MESSEJANA II
A2: INTERMEDIAÇÃO DE JULHO
A3: NOME | B3: APTO | C3: ALUGUEL | D3: DESCONTO | E3: ALUGUEL C/ DESCONTO | F3: GARAGEM | G3: IPTU | H3: SEG INC. | I3: TOTAL | J3: COMISSÃO | K3: REPASSE | L3: OBSERVAÇÃO | M3: VENC. | N3: CARÊNCIA
A4: JOÃO PAULO | B4: 1 | C4: =600 -> 600 | D4: =C4*10% -> 60 | E4: =C4-D4 -> 540 | F4: =50 -> 50 | G4: 0 | H4: =D38 -> 19.738333 | I4: =SUM(E4:H4) -> 609.73833 | J4: =60%*(C4+F4) -> 390 | K4: =I4-J4 -> 219.73833 | L4: DESCONTO 10% (2/12). SEGURO (1/6) | M4: 10 | N4: 11
A5: MATEUS | B5: 17 | C5: ='GERAL 2021'!G19 -> 640 | D5: =10%*C5 -> 64 | E5: =(C5-D5) -> 576 | F5: 0 | G5: 0 | H5: =D70 -> 19.811667 | I5: =SUM(E5:H5) -> 595.81167 | J5: =60%*(C5+F5) -> 384 | K5: =I5-J5 -> 211.81167 | L5: DESCONTO 10% (2/12). SEGURO (2/6). | M5: 10 | N5: 11
A6: TOTAL | C6: =SUM(C4:C5) -> 1240 | D6: =SUM(D4:D5) -> 124 | E6: =SUM(E4:E5) -> 1116 | F6: =SUM(F4:F5) -> 50 | G6: =SUM(G4:G5) -> 0 | H6: =SUM(H4:H5) -> 39.55 | I6: =SUM(I4:I5) -> 1205.55 | J6: =SUM(J4:J5) -> 774 | K6: =SUM(K4:K5) -> 431.55
A7: VIGÊNCIA DE AGOSTO DE 2021
A8: NOME | B8: APTO | C8: ALUGUEL | D8: DESCONTO | E8: ALUGUEL C/ DESCONTO | F8: GARAGEM | G8: IPTU | H8: SEG INC. | I8: TOTAL | J8: COMISSÃO | K8: REPASSE | L8: OBSERVAÇÃO | M8: VENC. | N8: CARÊNCIA
A9: JOÃO PAULO | B9: 1 | L9: INTERMEDIAÇÃO
B10: 2
B11: 3
B12: 4
B13: 5
B14: 6
B15: 7
B16: 8
B17: 9
A18: JOÃO CARLOS | B18: 10 | C18: 600 | D18: =10%*C18 -> 60 | E18: =C18-D18 -> 540 | F18: 0 | G18: 0 | H18: =D56 -> 17.825 | I18: =SUM(E18:H18) -> 557.825 | J18: =I18*7% -> 39.04775 | K18: =I18-J18 -> 518.77725 | L18: DESCONTO 10% (4/12). SEGURO (3/6). | M18: 10 | N18: 11
B19: 11
B20: 12
B21: 13
A22: CATIANA | B22: 15 | C22: 730 | D22: 60 | E22: =(C22-D22)/31*26 -> 561.93548 | F22: =50/31*26 -> 41.935484 | G22: =D67 -> 5.3552009 | H22: =D66 -> 19.99 | I22: =SUM(E22:H22) -> 629.21617 | J22: =7%*I22 -> 44.045132 | K22: =I22-J22 -> 585.17104 | L22: ALUGUEL, GARAGEM E IPTU PROPORCIONAIS A 26 DIAS (06/08 A 31/08). DESCONTO R$ 60,00 (1/12). IPTU (1/1). SEGURO (1/6) | M22: 10 | N22: 11
A23: VANESSA | B23: 16 | C23: ='GERAL 2021'!G18 -> 640 | D23: =10%*C23 -> 64 | E23: =C23-D23 -> 576 | F23: =60 -> 60 | G23: 0 | H23: =D68 -> 19.811667 | I23: =SUM(E23:H23) -> 655.81167 | J23: =7%*I23 -> 45.906817 | K23: =I23-J23 -> 609.90485 | L23: DESCONTO 10% (3/12). SEGURO (3/6). | M23: 10 | N23: 11
A24: MATEUS | B24: 17 | L24: INTERMEDIAÇÃO
A25: FREDSON | B25: 18 | C25: ='GERAL 2021'!G20 -> 650 | D25: =10%*C25 -> 65 | E25: =C25-D25 -> 585 | F25: =30 -> 30 | G25: 0 | H25: =D72 -> 19.836667 | I25: =SUM(E25:H25) -> 634.83667 | J25: =7%*I25 -> 44.438567 | K25: =I25-J25 -> 590.3981 | L25: DESCONTO 10% (3/12). SEGURO (3/6). | M25: 10 | N25: 11
A26: ERIVANDO | B26: 19 | C26: 600 | D26: =10%*C26 -> 60 | E26: =(C26-D26)/31*8 -> 139.35484 | F26: =50/31*8 -> 12.903226 | G26: =D75 -> 5.3552009 | H26: =D74 -> 19.738333 | I26: =SUM(E26:H26) -> 177.3516 | J26: =7%*I26 -> 12.414612 | K26: =I26-J26 -> 164.93699 | L26: ALUGUEL, GARAGEM E IPTU PROPORCIONAIS A 08 DIAS (24/08/2021 A 31/08/2021). DESCONTO 10% (1/12). IPTU (1/1). SEGURO (1/6) | M26: 10 | N26: 11
B27: 20
B28: 21
B29: 22
B30: 23
B31: 24
A32: SHIRLEY | B32: 25 | C32: =704 -> 704 | D32: =10%*C32 -> 70.4 | E32: =C32-D32 -> 633.6 | F32: =30 -> 30 | G32: 0 | H32: 19.99 | I32: =SUM(E32:H32) -> 683.59 | J32: =I32*7% -> 47.8513 | K32: =I32-J32 -> 635.7387 | L32: DESCONTO 10% (4/12). SEGURO (3/6). | M32: 10 | N32: 11
B33: 26
A34: LUIZA | B34: 27 | C34: =650 -> 650 | D34: =10%*C34 -> 65 | E34: =C34-D34 -> 585 | F34: =60 -> 60 | G34: 0 | H34: =D90 -> 19.836667 | I34: =SUM(E34:H34) -> 664.83667 | J34: =I34*7% -> 46.538567 | K34: =I34-J34 -> 618.2981 | L34: DESCONTO 10% (4/12). SEGURO (4/6). | M34: 10 | N34: 11
A35: TOTAL | C35: =SUM(C9:C34) -> 4574 | D35: =SUM(D9:D34) -> 444.4 | E35: =SUM(E9:E34) -> 3620.8903 | F35: =SUM(F9:F34) -> 234.83871 | G35: =SUM(G9:G34) -> 10.710402 | H35: =SUM(H9:H34) -> 137.02833 | I35: =SUM(I9:I34) -> 4003.4678 | J35: =SUM(J9:J34) -> 280.24274 | K35: =SUM(K9:K34) -> 3723.225
A37: OBSERVAÇÕES | L37: COMISSÃO ADMINISTRAÇÃO
A38: SEGURO 01 | B38: ='GERAL 2021'!K3 -> 118.43 | C38: 6 | D38: =B38/C38 -> 19.738333 | L38: COMISSÃO 7% | N38: =J35 -> 280.24274
A39: IPTU 01 | B39: ='GERAL 2021'!I3 -> 1.0710402 | C39: 6 | D39: =B39*C39 -> 6.4262411 | L39: INTERMEDIAÇÃO | N39: =J6 -> 774
A40: SEGURO 02
A41: IPTU 02
...

Sheet VIGÊNCIA SETEMBRO 2021
A1: GRAND MESSEJANA II
A2: INTERMEDIAÇÃO DE AGOSTO
A3: NOME | B3: APTO | C3: ALUGUEL | D3: DESCONTO | E3: ALUGUEL C/ DESCONTO | F3: GARAGEM | G3: IPTU | H3: SEG INC. | I3: TOTAL | J3: COMISSÃO | K3: REPASSE | L3: OBSERVAÇÃO | M3: VENC. | N3: CARÊNCIA
A4: CATIANA | B4: 15 | C4: 730 | D4: 60 | E4: =(C4-D4) -> 670 | F4: =50 -> 50 | G4: 0 | H4: =D71 -> 19.99 | I4: =SUM(E4:H4) -> 739.99 | J4: =60%*(C4+F4) -> 468 | K4: =I4-J4 -> 271.99 | L4: DESCONTO R$ 60,00 (2/12). SEGURO (2/6). | M4: 10 | N4: 11
A5: ERIVANDO | B5: 19 | C5: 600 | D5: =10%*C5 -> 60 | E5: =(C5-D5) -> 540 | F5: =50 -> 50 | G5: 0 | H5: =D79 -> 19.738333 | I5: =SUM(E5:H5) -> 609.73833 | J5: =60%*(C5+F5) -> 390 | K5: =I5-J5 -> 219.73833 | L5: DESCONTO 10% (2/12). SEGURO (2/6). | M5: 10 | N5: 11
A6: TOTAL | C6: =SUM(C4:C5) -> 1330 | D6: =SUM(D4:D5) -> 120 | E6: =SUM(E4:E5) -> 1210 | F6: =SUM(F4:F5) -> 100 | G6: =SUM(G4:G5) -> 0 | H6: =SUM(H4:H5) -> 39.728333 | I6: =SUM(I4:I5) -> 1349.7283 | J6: =SUM(J4:J5) -> 858 | K6: =SUM(K4:K5) -> 491.72833
A7: VIGÊNCIA DE SETEMBRO DE 2021
A8: NOME | B8: APTO | C8: ALUGUEL | D8: DESCONTO | E8: ALUGUEL C/ DESCONTO | F8: GARAGEM | G8: IPTU | H8: SEG INC. | I8: TOTAL | J8: COMISSÃO | K8: REPASSE | L8: OBSERVAÇÃO | M8: VENC. | N8: CARÊNCIA
A9: JOÃO PAULO | B9: 1 | C9: 0 | D9: =C9*10% -> 0 | E9: =C9-D9 -> 0 | F9: 0 | G9: 0 | H9: 0 | I9: =SUM(E9:H9) -> 0 | J9: =7%*I9 -> 0 | K9: =I9-J9 -> 0 | L9: INADIMPLÊNCIA | M9: 10 | N9: 11
B10: 2 | J10: =7%*I10 -> 0
B11: 3 | J11: =7%*I11 -> 0
B12: 4 | J12: =7%*I12 -> 0
B13: 5 | J13: =7%*I13 -> 0
B14: 6 | J14: =7%*I14 -> 0
B15: 7 | J15: =7%*I15 -> 0
B16: 8 | J16: =7%*I16 -> 0
B17: 9 | J17: =7%*I17 -> 0
A18: JOÃO CARLOS | B18: 10 | C18: 600 | D18: =10%*C18 -> 60 | E18: =C18-D18 -> 540 | F18: 0 | G18: 0 | H18: =D61 -> 17.825 | I18: =SUM(E18:H18) -> 557.825 | J18: =7%*I18 -> 39.04775 | K18: =I18-J18 -> 518.77725 | L18: DESCONTO 10% (5/12). SEGURO (4/6). | M18: 10 | N18: 11
B19: 11 | J19: =7%*I19 -> 0
B20: 12 | J20: =7%*I20 -> 0
B21: 13 | J21: =7%*I21 -> 0
B22: 14 | J22: =7%*I22 -> 0
A23: CATIANA | B23: 15 | J23: =7%*I23 -> 0 | L23: INTERMEDIAÇÃO
A24: VANESSA | B24: 16 | C24: ='GERAL 2021'!G18 -> 640 | D24: =10%*C24 -> 64 | E24: =C24-D24 -> 576 | F24: =60 -> 60 | G24: 0 | H24: =D73 -> 19.811667 | I24: =SUM(E24:H24) -> 655.81167 | J24: =7%*I24 -> 45.906817 | K24: =I24-J24 -> 609.90485 | L24: DESCONTO 10% (4/12). SEGURO (4/6). | M24: 10 | N24: 11
A25: MATEUS | B25: 17 | C25: ='GERAL 2021'!G19 -> 640 | D25: =10%*C25 -> 64 | E25: =(C25-D25) -> 576 | F25: 0 | G25: 0 | H25: =D75 -> 19.811667 | I25: =SUM(E25:H25) -> 595.81167 | J25: =7%*I25 -> 41.706817 | K25: =I25-J25 -> 554.10485 | L25: DESCONTO 10% (3/12). SEGURO (3/6). | M25: 10 | N25: 11
A26: FREDSON | B26: 18 | C26: ='GERAL 2021'!G20 -> 650 | D26: =10%*C26 -> 65 | E26: =C26-D26 -> 585 | F26: =30 -> 30 | G26: 0 | H26: =D77 -> 19.836667 | I26: =SUM(E26:H26) -> 634.83667 | J26: =7%*I26 -> 44.438567 | K26: =I26-J26 -> 590.3981 | L26: DESCONTO 10% (4/12). SEGURO (4/6). | M26: 10 | N26: 11
A27: ERIVANDO | B27: 19 | J27: =7%*I27 -> 0 | L27: INTERMEDIAÇÃO
B28: 20 | J28: =7%*I28 -> 0
B29: 21 | J29: =7%*I29 -> 0
B30: 22 | J30: =7%*I30 -> 0
B31: 23 | J31: =7%*I31 -> 0
B32: 24 | J32: =7%*I32 -> 0
A33: SHIRLEY | B33: 25 | C33: =704 -> 704 | D33: =10%*C33 -> 70.4 | E33: =C33-D33 -> 633.6 | F33: =30 -> 30 | G33: 0 | H33: 19.99 | I33: =SUM(E33:H33) -> 683.59 | J33: =7%*I33 -> 47.8513 | K33: =I33-J33 -> 635.7387 | L33: DESCONTO 10% (5/12). SEGURO (4/6). | M33: 10 | N33: 11
B34: 26 | J34: =7%*I34 -> 0
A35: LUIZA | B35: 27 | C35: =650 -> 650 | D35: =10%*C35 -> 65 | E35: =C35-D35 -> 585 | F35: =60 -> 60 | G35: 0 | H35: =D95 -> 19.836667 | I35: =SUM(E35:H35) -> 664.83667 | J35: =7%*I35 -> 46.538567 | K35: =I35-J35 -> 618.2981 | L35: DESCONTO 10% (5/12). SEGURO (5/6). | M35: 10 | N35: 11
A36: TOTAL | C36: =SUM(C9:C35) -> 3884 | D36: =SUM(D9:D35) -> 388.4 | E36: =SUM(E9:E35) -> 3495.6 | F36: =SUM(F9:F35) -> 180 | G36: =SUM(G9:G35) -> 0 | H36: =SUM(H9:H35) -> 117.11167 | I36: =SUM(I9:I35) -> 3792.7117 | J36: =SUM(J9:J35) -> 265.48982 | K36: =SUM(K9:K35) -> 3527.2218
A37: INADIMPLÊNCIAS
A38: NOME | B38: APTO | C38: PRINCIPAL | D38: CONDIÇÃO | I38: R$ PARCELA | L38: OBSERVAÇÃO | M38: VENC. | N38: CARÊNCIA
A39: JOÃO PAULO | B39: 1 | C39: =600+50+19.74 -> 669.74 | D39: R$ 600,00 (ALUGUEL SETEMBRO) + R$ 50,00 (GARAGEM) + R$ 19,74 (SEGURO 2/6). | I39: =600+50+19.74 -> 669.74 | L39: ALUGUEL DE SETEMBRO. PERDA DO DESCONTO (3/12). SEGURO (2/6). | M39: 10 | N39: 11
A40: TOTAL | I40: =SUM(I39) -> 669.74
...

Sheet VIGÊNCIA OUTUBRO 2021
A1: GRAND MESSEJANA II
A2: VIGÊNCIA DE OUTUBRO DE 2021
A3: NOME | B3: APTO | C3: ALUGUEL | D3: DESCONTO | E3: ALUGUEL C/ DESCONTO | F3: GARAGEM | G3: IPTU | H3: SEG INC. | I3: TOTAL | J3: COMISSÃO | K3: REPASSE | L3: OBSERVAÇÃO | M3: VENC. | N3: CARÊNCIA
A4: JOÃO PAULO | B4: 1 | C4: 0 | D4: =C4*10% -> 0 | E4: =C4-D4 -> 0 | F4: 0 | G4: 0 | H4: 0 | I4: =SUM(E4:H4) -> 0 | J4: =7%*I4 -> 0 | K4: =I4-J4 -> 0 | L4: INADIMPLÊNCIA | M4: 10 | N4: 11
B5: 2 | J5: =7%*I5 -> 0
B6: 3 | J6: =7%*I6 -> 0
B7: 4 | J7: =7%*I7 -> 0
B8: 5 | J8: =7%*I8 -> 0
B9: 6 | J9: =7%*I9 -> 0
B10: 7 | J10: =7%*I10 -> 0
B11: 8 | J11: =7%*I11 -> 0
B12: 9 | J12: =7%*I12 -> 0
A13: JOÃO CARLOS | B13: 10 | C13: 600 | D13: =10%*C13 -> 60 | E13: =C13-D13 -> 540 | F13: 0 | G13: 0 | H13: =D60 -> 17.825 | I13: =SUM(E13:H13) -> 557.825 | J13: =7%*I13 -> 39.04775 | K13: =I13-J13 -> 518.77725 | L13: DESCONTO 10% (6/12). SEGURO (5/6). | M13: 10 | N13: 11
B14: 11 | J14: =7%*I14 -> 0
B15: 12 | J15: =7%*I15 -> 0
B16: 13 | J16: =7%*I16 -> 0
B17: 14 | J17: =7%*I17 -> 0
A18: CATIANA | B18: 15 | C18: 730 | D18: 60 | E18: =(C18-D18) -> 670 | F18: =50 -> 50 | G18: 0 | H18: =D70 -> 19.99 | I18: =SUM(E18:H18) -> 739.99 | J18: =7%*I18 -> 51.7993 | K18: =I18-J18 -> 688.1907 | L18: DESCONTO R$ 60,00 (3/12). SEGURO (3/6). | M18: 10 | N18: 11
A19: VANESSA | B19: 16 | C19: ='GERAL 2021'!G18 -> 640 | D19: =10%*C19 -> 64 | E19: =C19-D19 -> 576 | F19: =60 -> 60 | G19: 0 | H19: =D72 -> 19.811667 | I19: =SUM(E19:H19) -> 655.81167 | J19: =7%*I19 -> 45.906817 | K19: =I19-J19 -> 609.90485 | L19: DESCONTO 10% (5/12). SEGURO (5/6). | M19: 10 | N19: 11
A20: MATEUS | B20: 17 | C20: ='GERAL 2021'!G19 -> 640 | D20: =10%*C20 -> 64 | E20: =(C20-D20) -> 576 | F20: 0 | G20: 0 | H20: =D74 -> 19.811667 | I20: =SUM(E20:H20) -> 595.81167 | J20: =7%*I20 -> 41.706817 | K20: =I20-J20 -> 554.10485 | L20: DESCONTO 10% (4/12). SEGURO (4/6). | M20: 10 | N20: 11
A21: FREDSON | B21: 18 | C21: ='GERAL 2021'!G20 -> 650 | D21: =10%*C21 -> 65 | E21: =C21-D21 -> 585 | F21: =30 -> 30 | G21: 0 | H21: =D76 -> 19.836667 | I21: =SUM(E21:H21) -> 634.83667 | J21: =7%*I21 -> 44.438567 | K21: =I21-J21 -> 590.3981 | L21: DESCONTO 10% (5/12). SEGURO (5/6). | M21: 10 | N21: 11
A22: ERIVANDO | B22: 19 | C22: 600 | D22: =10%*C22 -> 60 | E22: =(C22-D22) -> 540 | F22: =50 -> 50 | G22: 0 | H22: =D78 -> 19.738333 | I22: =SUM(E22:H22) -> 609.73833 | J22: =7%*I22 -> 42.681683 | K22: =I22-J22 -> 567.05665 | L22: DESCONTO 10% (3/12). SEGURO (3/6). | M22: 10 | N22: 11
B23: 20 | J23: =7%*I23 -> 0
B24: 21 | J24: =7%*I24 -> 0
B25: 22 | J25: =7%*I25 -> 0
B26: 23 | J26: =7%*I26 -> 0
B27: 24 | J27: =7%*I27 -> 0
A28: SHIRLEY | B28: 25 | C28: =704 -> 704 | D28: =10%*C28 -> 70.4 | E28: =C28-D28 -> 633.6 | F28: =30 -> 30 | G28: 0 | H28: 19.99 | I28: =SUM(E28:H28) -> 683.59 | J28: =7%*I28 -> 47.8513 | K28: =I28-J28 -> 635.7387 | L28: DESCONTO 10% (6/12). SEGURO (5/6). | M28: 10 | N28: 11
B29: 26 | J29: =7%*I29 -> 0
A30: LUIZA | B30: 27 | C30: =650 -> 650 | D30: =10%*C30 -> 65 | E30: =C30-D30 -> 585 | F30: =60 -> 60 | G30: 0 | H30: =D94 -> 19.836667 | I30: =SUM(E30:H30) -> 664.83667 | J30: =7%*I30 -> 46.538567 | K30: =I30-J30 -> 618.2981 | L30: DESCONTO 10% (6/12). SEGURO (6/6). | M30: 10 | N30: 11
A31: TOTAL | C31: =SUM(C4:C30) -> 5214 | D31: =SUM(D4:D30) -> 508.4 | E31: =SUM(E4:E30) -> 4705.6 | F31: =SUM(F4:F30) -> 280 | G31: =SUM(G4:G30) -> 0 | H31: =SUM(H4:H30) -> 156.84 | I31: =SUM(I4:I30) -> 5142.44 | J31: =SUM(J4:J30) -> 359.9708 | K31: =SUM(K4:K30) -> 4782.4692
A32: ALUGUÉIS ATRASADOS/ACORDOS/RESCISÕES RECEBIDAS EM OUTUBRO 2021
A33: NOME | B33: APTO | C33: ALUGUEL | D33: GARAGEM | E33: IPTU | F33: SEGURO | G33: MULTA | H33: JUROS | I33: TOTAL | J33: COMISSÃO | K33: REPASSE | L33: OBSERVAÇÃO | M33: VENC. | N33: CARÊNCIA
A34: JOÃO PAULO | B34: 1 | C34: 600 | D34: 50 | E34: 0 | F34: 19.74 | G34: =10%*(C34+D34+F34) -> 66.974 | H34: 4.46 | I34: =SUM(C34:H34) -> 741.174 | J34: =7%*I34 -> 51.88218 | K34: =I34-J34 -> 689.29182 | L34: ALUGUEL DE SETEMBRO. PERDA DO DESCONTO (3/12). SEGURO (2/6). PAGO DIA 29/10/2021. | M34: 10 | N34: 11
A35: TOTAL | I35: =SUM(I34) -> 741.174
A36: INADIMPLÊNCIAS
A37: NOME | B37: APTO | C37: PRINCIPAL | D37: CONDIÇÃO | I37: TOTAL | L37: OBSERVAÇÃO | M37: VENC. | N37: CARÊNCIA
A38: JOÃO PAULO | B38: 1 | C38: =600+50+19.74 -> 669.74 | D38: R$ 600,00 (ALUGUEL OUTUBRO) + R$ 50,00 (GARAGEM) + R$ 19,74 (SEGURO 2/6). | I38: =600+50+19.74 -> 669.74 | L38: ALUGUEL DE OUTUBRO. PERDA DO DESCONTO (4/12). SEGURO (3/6). | M38: 10 | N38: 11
A39: TOTAL | I39: =SUM(I38) -> 669.74
A41: OBSERVAÇÕES | L41: COMISSÃO ADMINISTRAÇÃO
...

Sheet VIGÊNCIA NOVEMBRO 2021
A1: GRAND MESSEJANA II
A2: VIGÊNCIA DE NOVEMBRO DE 2021
A3: NOME | B3: APTO | C3: ALUGUEL | D3: DESCONTO | E3: ALUGUEL C/ DESCONTO | F3: GARAGEM | G3: IPTU | H3: SEG INC. | I3: TOTAL | J3: COMISSÃO | K3: REPASSE | L3: OBSERVAÇÃO | M3: VENC. | N3: CARÊNCIA
A4: JOÃO PAULO | B4: 1 | C4: 0 | D4: =C4*10% -> 0 | E4: =C4-D4 -> 0 | F4: 0 | G4: 0 | H4: 0 | I4: =SUM(E4:H4) -> 0 | J4: =7%*I4 -> 0 | K4: =I4-J4 -> 0 | L4: INADIMPLÊNCIA | M4: 10 | N4: 11
B5: 2 | J5: =7%*I5 -> 0
B6: 3 | J6: =7%*I6 -> 0
B7: 4 | J7: =7%*I7 -> 0
B8: 5 | J8: =7%*I8 -> 0
B9: 6 | J9: =7%*I9 -> 0
B10: 7 | J10: =7%*I10 -> 0
B11: 8 | J11: =7%*I11 -> 0
B12: 9 | J12: =7%*I12 -> 0
A13: JOÃO CARLOS | B13: 10 | C13: 600 | D13: =10%*C13 -> 60 | E13: =C13-D13 -> 540 | F13: 0 | G13: 0 | H13: =D57 -> 17.825 | I13: =SUM(E13:H13) -> 557.825 | J13: =7%*I13 -> 39.04775 | K13: =I13-J13 -> 518.77725 | L13: DESCONTO 10% (7/12). SEGURO (6/6). | M13: 10 | N13: 11
B14: 11 | J14: =7%*I14 -> 0
B15: 12 | J15: =7%*I15 -> 0
B16: 13 | J16: =7%*I16 -> 0
B17: 14 | J17: =7%*I17 -> 0
A18: CATIANA | B18: 15 | C18: 730 | D18: 60 | E18: =(C18-D18) -> 670 | F18: =50 -> 50 | G18: 0 | H18: =D67 -> 19.99 | I18: =SUM(E18:H18) -> 739.99 | J18: =7%*I18 -> 51.7993 | K18: =I18-J18 -> 688.1907 | L18: DESCONTO R$ 60,00 (4/12). SEGURO (4/6). | M18: 10 | N18: 11
A19: VANESSA | B19: 16 | C19: ='GERAL 2021'!G18 -> 640 | D19: =10%*C19 -> 64 | E19: =C19-D19 -> 576 | F19: =60 -> 60 | G19: 0 | H19: =D69 -> 19.811667 | I19: =SUM(E19:H19) -> 655.81167 | J19: =7%*I19 -> 45.906817 | K19: =I19-J19 -> 609.90485 | L19: DESCONTO 10% (6/12). SEGURO (6/6). | M19: 10 | N19: 11
A20: MATEUS | B20: 17 | C20: ='GERAL 2021'!G19 -> 640 | D20: =10%*C20 -> 64 | E20: =(C20-D20) -> 576 | F20: 0 | G20: 0 | H20: =D71 -> 19.811667 | I20: =SUM(E20:H20) -> 595.81167 | J20: =7%*I20 -> 41.706817 | K20: =I20-J20 -> 554.10485 | L20: DESCONTO 10% (5/12). SEGURO (5/6). | M20: 10 | N20: 11
A21: FREDSON | B21: 18 | C21: ='GERAL 2021'!G20 -> 650 | D21: =10%*C21 -> 65 | E21: =C21-D21 -> 585 | F21: =30 -> 30 | G21: 0 | H21: =D73 -> 19.836667 | I21: =SUM(E21:H21) -> 634.83667 | J21: =7%*I21 -> 44.438567 | K21: =I21-J21 -> 590.3981 | L21: DESCONTO 10% (6/12). SEGURO (6/6). | M21: 10 | N21: 11
A22: ERIVANDO | B22: 19 | C22: 600 | D22: =10%*C22 -> 60 | E22: =(C22-D22) -> 540 | F22: =50 -> 50 | G22: 0 | H22: =D75 -> 19.738333 | I22: =SUM(E22:H22) -> 609.73833 | J22: =7%*I22 -> 42.681683 | K22: =I22-J22 -> 567.05665 | L22: DESCONTO 10% (4/12). SEGURO (4/6). | M22: 10 | N22: 11
B23: 20 | J23: =7%*I23 -> 0
B24: 21 | J24: =7%*I24 -> 0
B25: 22 | J25: =7%*I25 -> 0
B26: 23 | J26: =7%*I26 -> 0
B27: 24 | J27: =7%*I27 -> 0
A28: SHIRLEY | B28: 25 | C28: =704 -> 704 | D28: =10%*C28 -> 70.4 | E28: =C28-D28 -> 633.6 | F28: =30 -> 30 | G28: 0 | H28: 19.99 | I28: =SUM(E28:H28) -> 683.59 | J28: =7%*I28 -> 47.8513 | K28: =I28-J28 -> 635.7387 | L28: DESCONTO 10% (7/12). SEGURO (6/6). | M28: 10 | N28: 11
B29: 26 | J29: =7%*I29 -> 0
A30: LUIZA | B30: 27 | C30: =650 -> 650 | D30: =10%*C30 -> 65 | E30: =C30-D30 -> 585 | F30: =60 -> 60 | G30: 0 | H30: 0 | I30: =SUM(E30:H30) -> 645 | J30: =7%*I30 -> 45.15 | K30: =I30-J30 -> 599.85 | L30: DESCONTO 10% (7/12). SEGURO QUITADO. | M30: 10 | N30: 11
A31: TOTAL | C31: =SUM(C4:C30) -> 5214 | D31: =SUM(D4:D30) -> 508.4 | E31: =SUM(E4:E30) -> 4705.6 | F31: =SUM(F4:F30) -> 280 | G31: =SUM(G4:G30) -> 0 | H31: =SUM(H4:H30) -> 137.00333 | I31: =SUM(I4:I30) -> 5122.6033 | J31: =SUM(J4:J30) -> 358.58223 | K31: =SUM(K4:K30) -> 4764.0211
A32: INADIMPLÊNCIAS
A33: NOME | B33: APTO | C33: PRINCIPAL | D33: CONDIÇÃO | I33: TOTAL | L33: OBSERVAÇÃO | M33: VENC. | N33: CARÊNCIA
A34: JOÃO PAULO | B34: 1 | C34: =600+50+19.74 -> 669.74 | D34: R$ 600,00 (ALUGUEL OUTUBRO) + R$ 50,00 (GARAGEM) + R$ 19,74 (SEGURO 3/6). | I34: =600+50+19.74 -> 669.74 | L34: ALUGUEL DE OUTUBRO. PERDA DO DESCONTO (4/12). SEGURO (3/6). | M34: 10 | N34: 11
A35: JOÃO PAULO | B35: 1 | C35: =600+50+19.74 -> 669.74 | D35: R$ 600,00 (ALUGUEL NOVEMBRO) + R$ 50,00 (GARAGEM) + R$ 19,74 (SEGURO 4/6). | I35: =600+50+19.74 -> 669.74 | L35: ALUGUEL DE NOVEMBRO. PERDA DO DESCONTO (5/12). SEGURO (4/6). | M35: 10 | N35: 11
A36: TOTAL | I36: =SUM(I34:I35) -> 1339.48
A38: OBSERVAÇÕES | L38: COMISSÃO ADMINISTRAÇÃO
A39: SEGURO 01 | B39: ='GERAL 2021'!K3 -> 118.43 | C39: 6 | D39: =B39/C39 -> 19.738333 | L39: COMISSÃO 7% | N39: =J31 -> 358.58223
A40: IPTU 01 | B40: ='GERAL 2021'!I3 -> 1.0710402 | C40: 6 | D40: =B40*C40 -> 6.4262411
A41: SEGURO 02
...

Sheet VIGÊNCIA DEZEMBRO 2021
A1: GRAND MESSEJANA II
A2: VIGÊNCIA DE DEZEMBRO DE 2021
A3: NOME | B3: APTO | C3: ALUGUEL | D3: DESCONTO | E3: ALUGUEL C/ DESCONTO | F3: GARAGEM | G3: IPTU | H3: SEG INC. | I3: TOTAL | J3: COMISSÃO | K3: REPASSE | L3: OBSERVAÇÃO | M3: VENC. | N3: CARÊNCIA
A4: JOÃO PAULO | B4: 1 | C4: 0 | D4: 0 | E4: =C4-D4 -> 0 | F4: 0 | G4: 0 | H4: 0 | I4: =SUM(E4:H4) -> 0 | J4: =7%*I4 -> 0 | K4: =I4-J4 -> 0 | L4: INADIMPLÊNCIA | M4: 10 | N4: 11
B5: 2 | J5: =7%*I5 -> 0
B6: 3 | J6: =7%*I6 -> 0
B7: 4 | J7: =7%*I7 -> 0
B8: 5 | J8: =7%*I8 -> 0
B9: 6 | J9: =7%*I9 -> 0
B10: 7 | J10: =7%*I10 -> 0
B11: 8 | J11: =7%*I11 -> 0
B12: 9 | J12: =7%*I12 -> 0
A13: JOÃO CARLOS | B13: 10 | C13: 600 | D13: =10%*C13 -> 60 | E13: =C13-D13 -> 540 | F13: 0 | G13: 0 | H13: 0 | I13: =SUM(E13:H13) -> 540 | J13: =7%*I13 -> 37.8 | K13: =I13-J13 -> 502.2 | L13: DESCONTO 10% (8/12). SEGURO QUITADO. | M13: 10 | N13: 11
B14: 11 | J14: =7%*I14 -> 0
B15: 12 | J15: =7%*I15 -> 0
B16: 13 | J16: =7%*I16 -> 0
B17: 14 | J17: =7%*I17 -> 0
A18: CATIANA | B18: 15 | C18: 730 | D18: 60 | E18: =(C18-D18) -> 670 | F18: =50 -> 50 | G18: 0 | H18: =D68 -> 19.99 | I18: =SUM(E18:H18) -> 739.99 | J18: =7%*I18 -> 51.7993 | K18: =I18-J18 -> 688.1907 | L18: DESCONTO R$ 60,00 (5/12). SEGURO (5/6). | M18: 10 | N18: 11
A19: VANESSA | B19: 16 | C19: ='GERAL 2021'!G18 -> 640 | D19: =10%*C19 -> 64 | E19: =C19-D19 -> 576 | F19: =60 -> 60 | G19: 0 | H19: 0 | I19: =SUM(E19:H19) -> 636 | J19: =7%*I19 -> 44.52 | K19: =I19-J19 -> 591.48 | L19: DESCONTO 10% (7/12). SEGURO QUITADO. | M19: 10 | N19: 11
A20: MATEUS | B20: 17 | C20: ='GERAL 2021'!G19 -> 640 | D20: =10%*C20 -> 64 | E20: =(C20-D20) -> 576 | F20: 0 | G20: 0 | H20: =D72 -> 19.811667 | I20: =SUM(E20:H20) -> 595.81167 | J20: =7%*I20 -> 41.706817 | K20: =I20-J20 -> 554.10485 | L20: DESCONTO 10% (6/12). SEGURO (6/6). | M20: 10 | N20: 11
A21: FREDSON | B21: 18 | C21: ='GERAL 2021'!G20 -> 650 | D21: =10%*C21 -> 65 | E21: =C21-D21 -> 585 | F21: =30 -> 30 | G21: 0 | H21: 0 | I21: =SUM(E21:H21) -> 615 | J21: =7%*I21 -> 43.05 | K21: =I21-J21 -> 571.95 | L21: DESCONTO 10% (7/12). SEGURO QUITADO. | M21: 10 | N21: 11
A22: ERIVANDO | B22: 19 | C22: 600 | D22: =10%*C22 -> 60 | E22: =(C22-D22) -> 540 | F22: =50 -> 50 | G22: 0 | H22: =D76 -> 19.738333 | I22: =SUM(E22:H22) -> 609.73833 | J22: =7%*I22 -> 42.681683 | K22: =I22-J22 -> 567.05665 | L22: DESCONTO 10% (5/12). SEGURO (5/6). | M22: 10 | N22: 11
B23: 20 | J23: =7%*I23 -> 0
B24: 21 | J24: =7%*I24 -> 0
B25: 22 | J25: =7%*I25 -> 0
B26: 23 | J26: =7%*I26 -> 0
B27: 24 | J27: =7%*I27 -> 0
A28: SHIRLEY | B28: 25 | C28: =704 -> 704 | D28: =10%*C28 -> 70.4 | E28: =C28-D28 -> 633.6 | F28: =30 -> 30 | G28: 0 | H28: 0 | I28: =SUM(E28:H28) -> 663.6 | J28: =7%*I28 -> 46.452 | K28: =I28-J28 -> 617.148 | L28: DESCONTO 10% (8/12). SEGURO QUITADO. | M28: 10 | N28: 11
B29: 26 | J29: =7%*I29 -> 0
A30: LUIZA | B30: 27 | C30: =650 -> 650 | D30: =10%*C30 -> 65 | E30: =C30-D30 -> 585 | F30: =60 -> 60 | G30: 0 | H30: 0 | I30: =SUM(E30:H30) -> 645 | J30: =7%*I30 -> 45.15 | K30: =I30-J30 -> 599.85 | L30: DESCONTO 10% (8/12). SEGURO QUITADO. | M30: 10 | N30: 11
A31: TOTAL | C31: =SUM(C4:C30) -> 5214 | D31: =SUM(D4:D30) -> 508.4 | E31: =SUM(E4:E30) -> 4705.6 | F31: =SUM(F4:F30) -> 280 | G31: =SUM(G4:G30) -> 0 | H31: =SUM(H4:H30) -> 59.54 | I31: =SUM(I4:I30) -> 5045.14 | J31: =SUM(J4:J30) -> 353.1598 | K31: =SUM(K4:K30) -> 4691.9802
A32: INADIMPLÊNCIAS
A33: NOME | B33: APTO | C33: PRINCIPAL | D33: CONDIÇÃO | I33: TOTAL | L33: OBSERVAÇÃO | M33: VENC. | N33: CARÊNCIA
A34: JOÃO PAULO | B34: 1 | C34: =600+50+19.74 -> 669.74 | D34: R$ 600,00 (ALUGUEL OUTUBRO) + R$ 50,00 (GARAGEM) + R$ 19,74 (SEGURO 3/6). | I34: =600+50+19.74 -> 669.74 | L34: ALUGUEL DE OUTUBRO. PERDA DO DESCONTO (4/12). SEGURO (3/6). | M34: 10 | N34: 11
A35: JOÃO PAULO | B35: 1 | C35: =600+50+19.74 -> 669.74 | D35: R$ 600,00 (ALUGUEL NOVEMBRO) + R$ 50,00 (GARAGEM) + R$ 19,74 (SEGURO 4/6). | I35: =600+50+19.74 -> 669.74 | L35: ALUGUEL DE NOVEMBRO. PERDA DO DESCONTO (5/12). SEGURO (4/6). | M35: 10 | N35: 11
A36: JOÃO PAULO | B36: 1 | C36: =600+50+19.74 -> 669.74 | D36: R$ 600,00 (ALUGUEL DEZEMBBRO) + R$ 50,00 (GARAGEM) + R$ 19,74 (SEGURO 5/6). | I36: =600+50+19.74 -> 669.74 | L36: ALUGUEL DE DEZEMBRO. PERDA DO DESCONTO (6/12). SEGURO (5/6). | M36: 10 | N36: 11
A37: TOTAL | I37: =SUM(I34:I36) -> 2009.22
A39: OBSERVAÇÕES | L39: COMISSÃO ADMINISTRAÇÃO
A40: SEGURO 01 | B40: ='GERAL 2021'!K3 -> 118.43 | C40: 6 | D40: =B40/C40 -> 19.738333 | L40: COMISSÃO 7% | N40: =J31 -> 353.1598
A41: IPTU 01 | B41: ='GERAL 2021'!I3 -> 1.0710402 | C41: 6 | D41: =B41*C41 -> 6.4262411
...

Sheet VIGÊNCIA JANEIRO 2022
A1: GRAND MESSEJANA II
A2: VIGÊNCIA DE JANEIRO 2022
A3: NOME | B3: APTO | C3: ALUGUEL | D3: DESCONTO | E3: ALUGUEL C/ DESCONTO | F3: GARAGEM | G3: IPTU | H3: SEG INC. | I3: TOTAL | J3: COMISSÃO | K3: REPASSE | L3: OBSERVAÇÃO | M3: VENC. | N3: CARÊNCIA
A4: JOÃO PAULO | B4: 1 | C4: 0 | D4: =10%*C4 -> 0 | E4: =C4-D4 -> 0 | F4: 0 | G4: 0 | H4: 0 | I4: =SUM(E4:H4) -> 0 | J4: =7%*I4 -> 0 | K4: =I4-J4 -> 0 | L4: INADIMPLÊNCIA | M4: 10 | N4: 11
B5: 2 | J5: =7%*I5 -> 0
B6: 3 | J6: =7%*I6 -> 0
B7: 4 | J7: =7%*I7 -> 0
B8: 5 | J8: =7%*I8 -> 0
B9: 6 | J9: =7%*I9 -> 0
B10: 7 | J10: =7%*I10 -> 0
B11: 8 | J11: =7%*I11 -> 0
A12: ALCIDES / RENÊ | B12: 9 | C12: ='GERAL 2022'!G11/31*12 -> 224.51613 | D12: 0 | E12: =C12-D12 -> 224.51613 | F12: =75/31*12 -> 29.032258 | G12: =D58/31*12 -> 1.0981194 | H12: =D57 -> 19.696667 | I12: =SUM(E12:H12) -> 274.34317 | J12: =7%*I12 -> 19.204022 | K12: =I12-J12 -> 255.13915 | L12: ALUGUEL, GARAGEM E IPTU DE 12 DIAS (20/01 A 31/01). SEM DESCONTO. SEGURO (1/6). IPTU (1/5). | M12: 10 | N12: 11
A13: JOÃO CARLOS | B13: 10 | C13: ='GERAL 2022'!G12 -> 600 | D13: =10%*C13 -> 60 | E13: =C13-D13 -> 540 | F13: 0 | G13: =D60 -> 2.8368085 | H13: 0 | I13: =SUM(E13:H13) -> 542.83681 | J13: =7%*I13 -> 37.998577 | K13: =I13-J13 -> 504.83823 | L13: DESCONTO 10% (9/12). SEGURO QUITADO. IPTU (1/5). | M13: 10 | N13: 11
B14: 11 | J14: =7%*I14 -> 0
B15: 12 | J15: =7%*I15 -> 0
B16: 13 | J16: =7%*I16 -> 0
B17: 14 | J17: =7%*I17 -> 0
A18: CATIANA | B18: 15 | C18: 730 | D18: 60 | E18: =(C18-D18) -> 670 | F18: =50 -> 50 | G18: =D70 -> 3.9715319 | H18: =D69 -> 19.99 | I18: =SUM(E18:H18) -> 743.96153 | J18: =7%*I18 -> 52.077307 | K18: =I18-J18 -> 691.88422 | L18: DESCONTO R$ 60,00 (6/12). SEGURO (6/6). IPTU (1/5). | M18: 10 | N18: 11
A19: VANESSA | B19: 16 | C19: ='GERAL 2022'!G18 -> 640 | D19: =10%*C19 -> 64 | E19: =C19-D19 -> 576 | F19: =60 -> 60 | G19: =D72 -> 2.8368085 | H19: 0 | I19: =SUM(E19:H19) -> 638.83681 | J19: =7%*I19 -> 44.718577 | K19: =I19-J19 -> 594.11823 | L19: DESCONTO 10% (8/12). SEGURO QUITADO. IPTU (1/5). | M19: 10 | N19: 11
A20: MATEUS | B20: 17 | C20: ='GERAL 2022'!G19 -> 640 | D20: =10%*C20 -> 64 | E20: =(C20-D20) -> 576 | F20: 0 | G20: =D74 -> 2.8368085 | H20: 0 | I20: =SUM(E20:H20) -> 578.83681 | J20: =7%*I20 -> 40.518577 | K20: =I20-J20 -> 538.31823 | L20: DESCONTO 10% (7/12). SEGURO QUITADO. IPTU (1/5). | M20: 10 | N20: 11
A21: FREDSON | B21: 18 | C21: ='GERAL 2022'!G20 -> 650 | D21: =10%*C21 -> 65 | E21: =C21-D21 -> 585 | F21: =30 -> 30 | G21: =D76 -> 2.8368085 | H21: 0 | I21: =SUM(E21:H21) -> 617.83681 | J21: =7%*I21 -> 43.248577 | K21: =I21-J21 -> 574.58823 | L21: DESCONTO 10% (8/12). SEGURO QUITADO. IPTU (1/5). | M21: 10 | N21: 11
A22: ERIVANDO | B22: 19 | C22: ='GERAL 2022'!G21 -> 600 | D22: =10%*C22 -> 60 | E22: =(C22-D22) -> 540 | F22: =50 -> 50 | G22: =D78 -> 2.8368085 | H22: =D77 -> 19.738333 | I22: =SUM(E22:H22) -> 612.57514 | J22: =7%*I22 -> 42.88026 | K22: =I22-J22 -> 569.69488 | L22: DESCONTO 10% (6/12). SEGURO (6/6). IPTU (1/5). | M22: 10 | N22: 11
B23: 20 | J23: =7%*I23 -> 0
B24: 21 | J24: =7%*I24 -> 0
B25: 22 | J25: =7%*I25 -> 0
B26: 23 | J26: =7%*I26 -> 0
B27: 24 | C27: ='VIGÊNCIA FEVEREIRO 2022'!C31 -> 0 | J27: =7%*I27 -> 0
A28: SHIRLEY | B28: 25 | C28: ='GERAL 2022'!G27 -> 704 | D28: =10%*C28 -> 70.4 | E28: =C28-D28 -> 633.6 | F28: =30 -> 30 | G28: =D90 -> 2.8368085 | H28: 0 | I28: =SUM(E28:H28) -> 666.43681 | J28: =7%*I28 -> 46.650577 | K28: =I28-J28 -> 619.78623 | L28: DESCONTO 10% (9/12). SEGURO QUITADO. IPTU (1/5). | M28: 10 | N28: 11
B29: 26 | J29: =7%*I29 -> 0
A30: LUIZA | B30: 27 | C30: ='GERAL 2022'!G29 -> 650 | D30: =10%*C30 -> 65 | E30: =C30-D30 -> 585 | F30: =60 -> 60 | G30: =D94 -> 2.8368085 | H30: 0 | I30: =SUM(E30:H30) -> 647.83681 | J30: =7%*I30 -> 45.348577 | K30: =I30-J30 -> 602.48823 | L30: DESCONTO 10% (9/12). SEGURO QUITADO. IPTU (1/5). | M30: 10 | N30: 11
A31: TOTAL | C31: =SUM(C4:C30) -> 5438.5161 | D31: =SUM(D4:D30) -> 508.4 | E31: =SUM(E4:E30) -> 4930.1161 | F31: =SUM(F4:F30) -> 309.03226 | G31: =SUM(G4:G30) -> 24.927311 | H31: =SUM(H4:H30) -> 59.425 | I31: =SUM(I4:I30) -> 5323.5007 | J31: =SUM(J4:J30) -> 372.64505 | K31: =SUM(K4:K30) -> 4950.8556
A32: INADIMPLÊNCIAS
A33: NOME | B33: APTO | C33: PRINCIPAL | D33: CONDIÇÃO | I33: TOTAL | L33: OBSERVAÇÃO | M33: VENC. | N33: CARÊNCIA
A34: JOÃO PAULO | B34: 1 | C34: =600+50+19.74 -> 669.74 | D34: R$ 600,00 (ALUGUEL OUTUBRO) + R$ 50,00 (GARAGEM) + R$ 19,74 (SEGURO 3/6). | I34: =600+50+19.74 -> 669.74 | L34: ALUGUEL DE OUTUBRO/2021. PERDA DO DESCONTO (4/12). SEGURO (3/6). | M34: 10 | N34: 11
A35: JOÃO PAULO | B35: 1 | C35: =600+50+19.74 -> 669.74 | D35: R$ 600,00 (ALUGUEL NOVEMBRO) + R$ 50,00 (GARAGEM) + R$ 19,74 (SEGURO 4/6). | I35: =600+50+19.74 -> 669.74 | L35: ALUGUEL DE NOVEMBRO/2021. PERDA DO DESCONTO (5/12). SEGURO (4/6). | M35: 10 | N35: 11
A36: JOÃO PAULO | B36: 1 | C36: =600+50+19.74 -> 669.74 | D36: R$ 600,00 (ALUGUEL DEZEMBRO) + R$ 50,00 (GARAGEM) + R$ 19,74 (SEGURO 5/6). | I36: =600+50+19.74 -> 669.74 | L36: ALUGUEL DE DEZEMBRO/2021. PERDA DO DESCONTO (6/12). SEGURO (5/6). | M36: 10 | N36: 11
A37: JOÃO PAULO | B37: 1 | C37: =600+50+19.74+2.84 -> 672.58 | D37: R$ 600,00 (ALUGUEL JANEIRO) + R$ 50,00 (GARAGEM) + R$ 19,74 (SEGURO 5/6). | I37: =600+50+19.74+2.84 -> 672.58 | L37: ALUGUEL DE JANEIRO/2022. PERDA DO DESCONTO (7/12). SEGURO (6/6). IPTU (1/5). | M37: 10 | N37: 11
A38: TOTAL | I38: =SUM(I34:I37) -> 2681.8
A40: OBSERVAÇÕES | L40: COMISSÃO ADMINISTRAÇÃO
A41: SEGURO 01 | B41: ='GERAL 2022'!J3 -> 118.43 | C41: 6 | D41: =B41/C41 -> 19.738333 | L41: COMISSÃO 7% | N41: =J31 -> 372.64505
...

Sheet VIGÊNCIA FEVEREIRO 2022
A1: GRAND MESSEJANA II
A2: INTERMEDIAÇÃO DE JANEIRO DE 2022
A3: NOME | B3: APTO | C3: ALUGUEL | D3: DESCONTO | E3: ALUGUEL C/ DESCONTO | F3: GARAGEM | G3: IPTU | H3: SEG INC. | I3: TOTAL | J3: COMISSÃO | K3: REPASSE | L3: OBSERVAÇÃO | M3: VENC. | N3: CARÊNCIA
A4: ALCIDES / RENÊ | B4: 9 | C4: ='GERAL 2022'!G11 -> 580 | D4: 0 | E4: =C4-D4 -> 580 | F4: 75 | G4: =D67 -> 2.8368085 | H4: =D66 -> 19.696667 | I4: =SUM(E4:H4) -> 677.53348 | J4: =60%*(C4+F4) -> 393 | K4: =I4-J4 -> 284.53348 | L4: SEM DESCONTO. SEGURO (2/6). IPTU (2/5). | M4: 10 | N4: 11
A5: TOTAL | C5: =SUM(C4:C4) -> 580 | D5: =SUM(D4:D4) -> 0 | E5: =SUM(E4:E4) -> 580 | F5: =SUM(F4:F4) -> 75 | G5: =SUM(G4:G4) -> 2.8368085 | H5: =SUM(H4:H4) -> 19.696667 | I5: =SUM(I4:I4) -> 677.53348 | J5: =SUM(J4:J4) -> 393 | K5: =SUM(K4:K4) -> 284.53348
A6: VIGÊNCIA DE FEVEREIRO 2022
A7: NOME | B7: APTO | C7: ALUGUEL | D7: DESCONTO | E7: ALUGUEL C/ DESCONTO | F7: GARAGEM | G7: IPTU | H7: SEG INC. | I7: TOTAL | J7: COMISSÃO | K7: REPASSE | L7: OBSERVAÇÃO | M7: VENC. | N7: CARÊNCIA
A8: JOÃO PAULO | B8: 1 | C8: 0 | D8: =10%*C8 -> 0 | E8: =C8-D8 -> 0 | F8: 0 | G8: 0 | H8: 0 | I8: =SUM(E8:H8) -> 0 | J8: =7%*I8 -> 0 | K8: =I8-J8 -> 0 | L8: INADIMPLÊNCIA | M8: 10 | N8: 11
B9: 2 | J9: =7%*I9 -> 0
B10: 3 | J10: =7%*I10 -> 0
A11: AMANDA | B11: 4 | C11: ='GERAL 2022'!G6/28*12 -> 235.71429 | D11: 0 | E11: =C11-D11 -> 235.71429 | F11: =50/28*12 -> 21.428571 | G11: =D57/28*12 -> 1.2157751 | H11: =D56 -> 19.641667 | I11: =SUM(E11:H11) -> 278.0003 | J11: =7%*I11 -> 19.460021 | K11: =I11-J11 -> 258.54028 | L11: PROPORCIONAL DE 12 DIAS (17/02 A 28/02). IPTU (2/5). SEGUROS (1/6). | M11: 10 | N11: 11
B12: 5 | J12: =7%*I12 -> 0
B13: 6 | J13: =7%*I13 -> 0
B14: 7 | J14: =7%*I14 -> 0
A15: ARMANDO | B15: 8 | C15: ='GERAL 2022'!G10/28*25 -> 544.64286 | D15: 0 | E15: =C15-D15 -> 544.64286 | F15: 0 | G15: =D65/28*25 -> 2.5328647 | H15: =D64 -> 19.755 | I15: =SUM(E15:H15) -> 566.93072 | J15: =7%*I15 -> 39.685151 | K15: =I15-J15 -> 527.24557 | L15: PROPORCIONAL DE 25 DIAS (04/02 A 28/02). IPTU (2/5). SEGUROS (1/6). | M15: 10 | N15: 11
A16: ALCIDES / RENÊ | B16: 9 | C16: ='GERAL 2022'!G11 -> 580 | D16: 0 | E16: =C16-D16 -> 580 | F16: 755 | G16: 2.84 | H16: 0 | I16: =SUM(E16:H16) -> 1337.84 | J16: =7%*I16 -> 93.6488 | K16: =I16-J16 -> 1244.1912 | L16: INTERMEDIAÇÃO | M16: 10 | N16: 11
A17: JOÃO CARLOS | B17: 10 | C17: ='GERAL 2022'!G12 -> 600 | D17: =10%*C17 -> 60 | E17: =C17-D17 -> 540 | F17: 0 | G17: =D69 -> 2.8368085 | H17: 0 | I17: =SUM(E17:H17) -> 542.83681 | J17: =7%*I17 -> 37.998577 | K17: =I17-J17 -> 504.83823 | L17: DESCONTO 10% (10/12). SEGURO QUITADO. IPTU (2/5). | M17: 10 | N17: 11
B18: 11 | J18: =7%*I18 -> 0
B19: 12 | J19: =7%*I19 -> 0
B20: 13 | J20: =7%*I20 -> 0
B21: 14 | J21: =7%*I21 -> 0
A22: CATIANA | B22: 15 | C22: 730 | D22: 60 | E22: =(C22-D22)/28*2 -> 47.857143 | F22: =50/28*2 -> 3.5714286 | G22: =D79/28*2 -> 0.28368085 | H22: 0 | I22: =SUM(E22:H22) -> 51.712252 | J22: =7%*I22 -> 3.6198577 | K22: =I22-J22 -> 48.092395 | L22: RESCISÃO. PROPORCIONAL 02 DIAS (01/02 A 02/02). DESCONTO R$ 60,00 (7/12). SEGURO QUITADO. IPTU (2/5). | M22: 10 | N22: 11
A23: BIANCA | B23: 15 | C23: ='GERAL 2022'!G40/28*6 -> 139.28571 | D23: 0 | E23: =C23-D23 -> 139.28571 | F23: =25/28*6 -> 5.3571429 | G23: =D81/28*6 -> 0.85104255 | H23: =D80 -> 19.836667 | I23: =SUM(E23:H23) -> 165.33057 | J23: =7%*I23 -> 11.57314 | K23: =I23-J23 -> 153.75743 | L23: PROPORCIONAL DE 06 DIAS (23/02 A 28/02). IPTU (2/5). SEGUROS (1/6). | M23: 10 | N23: 11
A24: VANESSA | B24: 16 | C24: ='GERAL 2022'!G18 -> 640 | D24: =10%*C24 -> 64 | E24: =C24-D24 -> 576 | F24: =60 -> 60 | G24: =D83 -> 2.8368085 | H24: 0 | I24: =SUM(E24:H24) -> 638.83681 | J24: =7%*I24 -> 44.718577 | K24: =I24-J24 -> 594.11823 | L24: DESCONTO 10% (9/12). SEGURO QUITADO. IPTU (2/5). | M24: 10 | N24: 11
A25: MATEUS | B25: 17 | C25: ='GERAL 2022'!G19 -> 640 | D25: =10%*C25 -> 64 | E25: =(C25-D25) -> 576 | F25: 0 | G25: =D85 -> 2.8368085 | H25: 0 | I25: =SUM(E25:H25) -> 578.83681 | J25: =7%*I25 -> 40.518577 | K25: =I25-J25 -> 538.31823 | L25: DESCONTO 10% (8/12). SEGURO QUITADO. IPTU (2/5). | M25: 10 | N25: 11
A26: FREDSON | B26: 18 | C26: ='GERAL 2022'!G20 -> 650 | D26: =10%*C26 -> 65 | E26: =C26-D26 -> 585 | F26: =30 -> 30 | G26: =D87 -> 2.8368085 | H26: 0 | I26: =SUM(E26:H26) -> 617.83681 | J26: =7%*I26 -> 43.248577 | K26: =I26-J26 -> 574.58823 | L26: DESCONTO 10% (9/12). SEGURO QUITADO. IPTU (2/5). | M26: 10 | N26: 11
A27: ERIVANDO | B27: 19 | C27: ='GERAL 2022'!G21 -> 600 | D27: =10%*C27 -> 60 | E27: =(C27-D27) -> 540 | F27: =50 -> 50 | G27: =D89 -> 2.8368085 | H27: 0 | I27: =SUM(E27:H27) -> 592.83681 | J27: =7%*I27 -> 41.498577 | K27: =I27-J27 -> 551.33823 | L27: DESCONTO 10% (7/12). SEGURO QUITADO. IPTU (2/5). | M27: 10 | N27: 11
B28: 20 | J28: =7%*I28 -> 0
B29: 21 | J29: =7%*I29 -> 0
B30: 22 | J30: =7%*I30 -> 0
B31: 23 | J31: =7%*I31 -> 0
A32: JOÃO LEVI | B32: 24 | C32: ='GERAL 2022'!G26 -> 650 | D32: 0 | E32: =C32-D32 -> 650 | F32: 50 | G32: =D99 -> 3.9715319 | H32: =D98 -> 19.836667 | I32: =SUM(E32:H32) -> 723.8082 | J32: =7%*I32 -> 50.666574 | K32: =I32-J32 -> 673.14162 | L32: IPTU (2/5). SEGURO (1/6). | M32: 10 | N32: 11
A33: SHIRLEY | B33: 25 | C33: ='GERAL 2022'!G27 -> 704 | D33: =10%*C33 -> 70.4 | E33: =C33-D33 -> 633.6 | F33: =30 -> 30 | G33: =D101 -> 2.8368085 | H33: 0 | I33: =SUM(E33:H33) -> 666.43681 | J33: =7%*I33 -> 46.650577 | K33: =I33-J33 -> 619.78623 | L33: DESCONTO 10% (10/12). SEGURO QUITADO. IPTU (2/5). | M33: 10 | N33: 11
B34: 26 | J34: =7%*I34 -> 0
A35: LUIZA | B35: 27 | C35: ='GERAL 2022'!G29 -> 650 | D35: =10%*C35 -> 65 | E35: =C35-D35 -> 585 | F35: =60 -> 60 | G35: =D105 -> 2.8368085 | H35: 0 | I35: =SUM(E35:H35) -> 647.83681 | J35: =7%*I35 -> 45.348577 | K35: =I35-J35 -> 602.48823 | L35: DESCONTO 10% (10/12). SEGURO QUITADO. IPTU (2/5). | M35: 10 | N35: 11
A36: TOTAL | C36: =SUM(C8:C35) -> 7363.6429 | D36: =SUM(D8:D35) -> 508.4 | E36: =SUM(E8:E35) -> 6233.1 | F36: =SUM(F8:F35) -> 1065.3571 | G36: =SUM(G8:G35) -> 31.552555 | H36: =SUM(H8:H35) -> 79.07 | I36: =SUM(I8:I35) -> 7409.0797 | J36: =SUM(J8:J35) -> 518.63558 | K36: =SUM(K8:K35) -> 6890.4441
A38: ACORDOS/RESCISÕES RECEBIDAS EM FEVEREIRO DE 2022
A39: NOME | B39: APTO | C39: PRINCIPAL | D39: CONDIÇÃO | I39: TOTAL | J39: COMISSÃO | K39: REPASSE | L39: OBSERVAÇÃO | M39: VENC. | N39: CARÊNCIA
A40: CATIANA | B40: 15 | C40: 1608 | D40: 1X DE R$ 1.608,00 | I40: 1608 | J40: =7%*I40 -> 112.56 | K40: =I40-J40 -> 1495.44 | L40: RESCISÃO. PAGO NO DIA 02/02/2022. | M40: 10 | N40: 11
A41: JOÃO PAULO | B41: 1 | C41: 1520 | D41: 1X DE R$ 1.520,00 | I41: 1520 | J41: =7%*I41 -> 106.4 | K41: =I41-J41 -> 1413.6 | L41: CAUÇÃO PARA PAGAMENTO DE PARTE DO DÉBITO. PAGO NO DIA 19/02/2022. | M41: 10 | N41: 11
...

Sheet VIGÊNCIA MARÇO 2022
A1: GRAND MESSEJANA II
A2: INTERMEDIAÇÃO DE FEVEREIRO DE 2022
A3: NOME | B3: APTO | C3: ALUGUEL | D3: DESCONTO | E3: ALUGUEL C/ DESCONTO | F3: GARAGEM | G3: IPTU | H3: SEG INC. | I3: TOTAL | J3: COMISSÃO | K3: REPASSE | L3: OBSERVAÇÃO | M3: VENC. | N3: CARÊNCIA
A4: AMANDA | B4: 4 | C4: ='GERAL 2022'!G6 -> 550 | D4: 0 | E4: =C4-D4 -> 550 | F4: 50 | G4: =D68 -> 2.8368085 | H4: 19.64 | I4: =SUM(E4:H4) -> 622.47681 | J4: =60%*(C4+F4) -> 360 | K4: =I4-J4 -> 262.47681 | L4: SEM DESCONTO. IPTU (3/5). SEGUROS (2/6). | M4: 10 | N4: 11
A5: ARMANDO | B5: 8 | C5: ='GERAL 2022'!G10 -> 610 | D5: 0 | E5: =C5-D5 -> 610 | F5: 0 | G5: 2.84 | H5: 19.76 | I5: =SUM(E5:H5) -> 632.6 | J5: =60%*(C5+F5) -> 366 | K5: =I5-J5 -> 266.6 | L5: SEM DESCONTO. IPTU (3/5). SEGUROS (2/6).
A6: BIANCA | B6: 15 | C6: ='GERAL 2022'!G40 -> 650 | D6: 0 | E6: =C6-D6 -> 650 | F6: 25 | G6: 3.97 | H6: 19.84 | I6: =SUM(E6:H6) -> 698.81 | J6: =60%*(C6+F6) -> 405 | K6: =I6-J6 -> 293.81 | L6: SEM DESCONTO. IPTU (3/5). SEGUROS (2/6).
A7: JOÃO LEVI | B7: 24 | C7: ='GERAL 2022'!G26 -> 650 | D7: 0 | E7: =C7-D7 -> 650 | F7: 50 | G7: 3.97 | H7: 19.84 | I7: =SUM(E7:H7) -> 723.81 | J7: =60%*(C7+F7) -> 420 | K7: =I7-J7 -> 303.81 | L7: SEM DESCONTO. IPTU (3/5). SEGUROS (2/6).
A8: TOTAL | C8: =SUM(C4:C7) -> 2460 | D8: =SUM(D4:D7) -> 0 | E8: =SUM(E4:E7) -> 2460 | F8: =SUM(F4:F7) -> 125 | G8: =SUM(G4:G7) -> 13.616809 | H8: =SUM(H4:H7) -> 79.08 | I8: =SUM(I4:I7) -> 2677.6968 | J8: =SUM(J4:J7) -> 1551 | K8: =SUM(K4:K7) -> 1126.6968
A9: VIGÊNCIA DE MARÇO 2022
A10: NOME | B10: APTO | C10: ALUGUEL | D10: DESCONTO | E10: ALUGUEL C/ DESCONTO | F10: GARAGEM | G10: IPTU | H10: SEG INC. | I10: TOTAL | J10: COMISSÃO | K10: REPASSE | L10: OBSERVAÇÃO | M10: VENC. | N10: CARÊNCIA
B11: 1
B12: 2 | J12: =7%*I12 -> 0
B13: 3 | J13: =7%*I13 -> 0
A14: AMANDA | B14: 4 | C14: 0 | D14: 0 | E14: =C14-D14 -> 0 | F14: 0 | G14: 0 | H14: 0 | I14: =SUM(E14:H14) -> 0 | J14: =7%*I14 -> 0 | K14: =I14-J14 -> 0 | L14: INTERMEDIAÇÃO | M14: 10 | N14: 11
B15: 5 | J15: =7%*I15 -> 0
A16: LIGIA | B16: 6 | C16: ='GERAL 2022'!G8/31*15 -> 314.51613 | D16: 0 | E16: =C16-D16 -> 314.51613 | F16: =25/31*15 -> 12.096774 | G16: =D62/31*15 -> 1.921709 | H16: =D61 -> 19.836667 | I16: =SUM(E16:H16) -> 348.37128 | J16: =7%*I16 -> 24.38599 | K16: =I16-J16 -> 323.98529 | L16: PROPORCIONAL DE 15 DIAS (17/03 A 31/03). IPTU (1/5). SEGUROS (1/6). | M16: 10 | N16: 11
B17: 7 | I17: 0 | J17: =7%*I17 -> 0
A18: ARMANDO | B18: 8 | C18: 0 | D18: 0 | E18: =C18-D18 -> 0 | F18: 0 | G18: 0 | H18: 0 | I18: =SUM(E18:H18) -> 0 | J18: =7%*I18 -> 0 | K18: =I18-J18 -> 0 | L18: INTERMEDIAÇÃO | M18: 10 | N18: 11
A19: ALCIDES / RENÊ | B19: 9 | C19: ='GERAL 2022'!G11 -> 580 | D19: 0 | E19: =C19-D19 -> 580 | F19: =50+(25/31*15) -> 62.096774 | G19: 2.84 | H19: 19.7 | I19: =SUM(E19:H19) -> 664.63677 | J19: =7%*I19 -> 46.524574 | K19: =I19-J19 -> 618.1122 | L19: RESCISÃO DE UMA VAGA DE MOTO DIA 17/03 (PROPORCIONAL DE 15 DIAS). SEM DESCONTO. SEGURO (3/6). IPTU (3/5). | M19: 10 | N19: 11
A20: JOÃO CARLOS | B20: 10 | C20: ='GERAL 2022'!G12 -> 600 | D20: =10%*C20 -> 60 | E20: =C20-D20 -> 540 | F20: 0 | G20: =D70 -> 2.8368085 | H20: 0 | I20: =SUM(E20:H20) -> 542.83681 | J20: =7%*I20 -> 37.998577 | K20: =I20-J20 -> 504.83823 | L20: DESCONTO 10% (10/12). SEGURO QUITADO. IPTU (2/5). | M20: 10 | N20: 11
B21: 11 | J21: =7%*I21 -> 0
B22: 12 | J22: =7%*I22 -> 0
B23: 13 | J23: =7%*I23 -> 0
A24: HOSANA | B24: 14 | C24: ='GERAL 2022'!G16/31*8 -> 141.93548 | D24: 0 | E24: =C24-D24 -> 141.93548 | F24: 0 | G24: =D78/31*8 -> 0.73207962 | H24: =D77 -> 19.641667 | I24: =SUM(E24:H24) -> 162.30923 | J24: =7%*I24 -> 11.361646 | K24: =I24-J24 -> 150.94758 | L24: PROPORCIONAL DE 8 DIAS (24/03 A 31/03). IPTU (1/5). SEGUROS (1/6). | M24: 10 | N24: 11
A25: BIANCA | B25: 15 | C25: 0 | D25: 0 | E25: =C25-D25 -> 0 | F25: 0 | G25: 0 | H25: 0 | I25: =SUM(E25:H25) -> 0 | J25: =7%*I25 -> 0 | K25: =I25-J25 -> 0 | L25: INTERMEDIAÇÃO | M25: 10 | N25: 11
A26: VANESSA | B26: 16 | C26: ='GERAL 2022'!G18 -> 640 | D26: =10%*C26 -> 64 | E26: =C26-D26 -> 576 | F26: =60 -> 60 | G26: =D84 -> 2.8368085 | H26: 0 | I26: =SUM(E26:H26) -> 638.83681 | J26: =7%*I26 -> 44.718577 | K26: =I26-J26 -> 594.11823 | L26: DESCONTO 10% (10/12). SEGURO QUITADO. IPTU (3/5). | M26: 10 | N26: 11
A27: MATEUS LEVI | B27: 17 | C27: ='GERAL 2022'!G19 -> 640 | D27: =10%*C27 -> 64 | E27: =(C27-D27) -> 576 | F27: 0 | G27: =D86 -> 2.8368085 | H27: 0 | I27: =SUM(E27:H27) -> 578.83681 | J27: =7%*I27 -> 40.518577 | K27: =I27-J27 -> 538.31823 | L27: DESCONTO 10% (9/12). SEGURO QUITADO. IPTU (3/5). | M27: 10 | N27: 11
A28: FREDSON | B28: 18 | C28: ='GERAL 2022'!G20 -> 650 | D28: =10%*C28 -> 65 | E28: =C28-D28 -> 585 | F28: =30 -> 30 | G28: =D88 -> 2.8368085 | H28: 0 | I28: =SUM(E28:H28) -> 617.83681 | J28: =7%*I28 -> 43.248577 | K28: =I28-J28 -> 574.58823 | L28: DESCONTO 10% (10/12). SEGURO QUITADO. IPTU (3/5). | M28: 10 | N28: 11
A29: ERIVANDO | B29: 19 | C29: ='GERAL 2022'!G21 -> 600 | D29: =10%*C29 -> 60 | E29: =(C29-D29) -> 540 | F29: =50 -> 50 | G29: =D90 -> 2.8368085 | H29: 0 | I29: =SUM(E29:H29) -> 592.83681 | J29: =7%*I29 -> 41.498577 | K29: =I29-J29 -> 551.33823 | L29: DESCONTO 10% (8/12). SEGURO QUITADO. IPTU (3/5). | M29: 10 | N29: 11
B30: 20 | J30: =7%*I30 -> 0
B31: 21 | J31: =7%*I31 -> 0
B32: 22 | J32: =7%*I32 -> 0
B33: 23 | J33: =7%*I33 -> 0
A34: JOÃO LEVI | B34: 24 | C34: 0 | D34: 0 | E34: =C34-D34 -> 0 | F34: 0 | G34: 0 | H34: 0 | I34: =SUM(E34:H34) -> 0 | J34: =7%*I34 -> 0 | K34: =I34-J34 -> 0 | L34: INTERMEDIAÇÃO | M34: 10 | N34: 11
A35: SHIRLEY | B35: 25 | C35: ='GERAL 2022'!G27 -> 704 | D35: =10%*C35 -> 70.4 | E35: =C35-D35 -> 633.6 | F35: =30 -> 30 | G35: =D102 -> 2.8368085 | H35: 0 | I35: =SUM(E35:H35) -> 666.43681 | J35: =7%*I35 -> 46.650577 | K35: =I35-J35 -> 619.78623 | L35: DESCONTO 10% (11/12). SEGURO QUITADO. IPTU (2/5). | M35: 10 | N35: 11
B36: 26 | J36: =7%*I36 -> 0
A37: LUIZA | B37: 27 | C37: ='GERAL 2022'!G29/31*29 -> 608.06452 | D37: =10%*C37 -> 60.806452 | E37: =C37-D37 -> 547.25806 | F37: =60/31*29 -> 56.129032 | G37: =D106/31*29 -> 2.6537886 | H37: 0 | I37: =SUM(E37:H37) -> 606.04089 | J37: =7%*I37 -> 42.422862 | K37: =I37-J37 -> 563.61802 | L37: RESCISÃO. PROPORCIONAL DE 01/03 A 29/03. DESCONTO 10% (11/12). SEGURO QUITADO. IPTU (3/5). | M37: 10 | N37: 11
A38: TOTAL | C38: =SUM(C11:C37) -> 5478.5161 | D38: =SUM(D11:D37) -> 444.20645 | E38: =SUM(E11:E37) -> 5034.3097 | F38: =SUM(F11:F37) -> 300.32258 | G38: =SUM(G11:G37) -> 25.168428 | H38: =SUM(H11:H37) -> 59.178333 | I38: =SUM(I11:I37) -> 5418.979 | J38: =SUM(J11:J37) -> 379.32853 | K38: =SUM(K11:K37) -> 5039.6505
A40: ACORDOS/RESCISÕES RECEBIDAS EM MARÇO DE 2022
A41: NOME | B41: APTO | C41: PRINCIPAL | D41: CONDIÇÃO | I41: TOTAL | J41: COMISSÃO | K41: REPASSE | L41: OBSERVAÇÃO | M41: VENC. | N41: CARÊNCIA
...

Sheet VIGÊNCIA ABRIL 2022
A1: GRAND MESSEJANA II
A2: INTERMEDIAÇÃO DE MARÇO DE 2022
A3: NOME | B3: APTO | C3: ALUGUEL | D3: DESCONTO | E3: ALUGUEL C/ DESCONTO | F3: GARAGEM | G3: IPTU | H3: SEG INC. | I3: TOTAL | J3: COMISSÃO | K3: REPASSE | L3: OBSERVAÇÃO | M3: VENC. | N3: CARÊNCIA
A4: LIGIA | B4: 6 | C4: ='GERAL 2022'!G8 -> 650 | D4: 0 | E4: =C4-D4 -> 650 | F4: =25 -> 25 | G4: =D55 -> 3.9715319 | H4: =D54 -> 19.836667 | I4: =SUM(E4:H4) -> 698.8082 | J4: =60%*(C4+F4) -> 405 | K4: =I4-J4 -> 293.8082 | L4: SEM DESCONTO. IPTU (2/5). SEGURO (2/6). | M4: 10 | N4: 11
A5: HOSANA | B5: 14 | C5: ='GERAL 2022'!G16 -> 550 | D5: 0 | E5: =C5-D5 -> 550 | F5: 0 | G5: =D71 -> 2.8368085 | H5: =D70 -> 19.641667 | I5: =SUM(E5:H5) -> 572.47848 | J5: =60%*(C5+F5) -> 330 | K5: =I5-J5 -> 242.47848 | L5: SEM DESCONTO. IPTU (2/5). SEGUROS (2/6). | M5: 10 | N5: 11
A6: TOTAL | C6: =SUM(C4:C5) -> 1200 | D6: =SUM(D4:D5) -> 0 | E6: =SUM(E4:E5) -> 1200 | F6: =SUM(F4:F5) -> 25 | G6: =SUM(G4:G5) -> 6.8083404 | H6: =SUM(H4:H5) -> 39.478333 | I6: =SUM(I4:I5) -> 1271.2867 | J6: =SUM(J4:J5) -> 735 | K6: =SUM(K4:K5) -> 536.28667
A7: VIGÊNCIA DE ABRIL 2022
A8: NOME | B8: APTO | C8: ALUGUEL | D8: DESCONTO | E8: ALUGUEL C/ DESCONTO | F8: GARAGEM | G8: IPTU | H8: SEG INC. | I8: TOTAL | J8: COMISSÃO | K8: REPASSE | L8: OBSERVAÇÃO | M8: VENC. | N8: CARÊNCIA
B9: 1
B10: 2 | J10: =7%*I10 -> 0
B11: 3 | J11: =7%*I11 -> 0
A12: AMANDA | B12: 4 | C12: ='GERAL 2022'!G16 -> 550 | D12: 0 | E12: =C12-D12 -> 550 | F12: 50 | G12: =D51 -> 2.8368085 | H12: =D50 -> 19.641667 | I12: =SUM(E12:H12) -> 622.47848 | J12: =7%*I12 -> 43.573493 | K12: =I12-J12 -> 578.90498 | L12: SEM DESCONTO. IPTU (4/5). SEGUROS (3/6). | M12: 10 | N12: 11
B13: 5 | J13: =7%*I13 -> 0
A14: LIGIA | B14: 6 | C14: 0 | D14: 0 | E14: =C14-D14 -> 0 | F14: 0 | G14: 0 | H14: 0 | I14: =SUM(E14:H14) -> 0 | J14: =7%*I14 -> 0 | K14: =I14-J14 -> 0 | L14: INTERMEDIAÇÃO | M14: 10 | N14: 11
B15: 7 | I15: 0 | J15: =7%*I15 -> 0
A16: ARMANDO | B16: 8 | C16: ='GERAL 2022'!G10 -> 610 | D16: 0 | E16: =C16-D16 -> 610 | F16: 0 | G16: =D59 -> 2.8368085 | H16: =D58 -> 19.755 | I16: =SUM(E16:H16) -> 632.59181 | J16: =7%*I16 -> 44.281427 | K16: =I16-J16 -> 588.31038 | L16: SEM DESCONTO. IPTU (4/5). SEGUROS (3/6). | M16: 10 | N16: 11
A17: ALCIDES / RENÊ | B17: 9 | C17: ='GERAL 2022'!G11 -> 580 | D17: 0 | E17: =C17-D17 -> 580 | F17: =50 -> 50 | G17: =D61 -> 2.8368085 | H17: =D60 -> 19.696667 | I17: =SUM(E17:H17) -> 652.53348 | J17: =7%*I17 -> 45.677343 | K17: =I17-J17 -> 606.85613 | L17: SEM DESCONTO. SEGURO (4/6). IPTU (4/5). | M17: 10 | N17: 11
B18: 10
A19: JOCÉLIO | B19: 11 | C19: ='GERAL 2022'!G13 -> 550 | D19: 0 | E19: =C19-D19 -> 550 | F19: 0 | G19: =D65 -> 2.8368085 | H19: =D64 -> 19.641667 | I19: =SUM(E19:H19) -> 572.47848 | J19: =7%*I19 -> 40.073493 | K19: =I19-J19 -> 532.40498 | L19: SEM DESCONTO. IPTU (1/5). SEGURO (1/6). | M19: 10 | N19: 11
B20: 12 | J20: =7%*I20 -> 0
B21: 13 | J21: =7%*I21 -> 0
A22: HOSANA | B22: 14 | C22: 0 | D22: 0 | E22: =C22-D22 -> 0 | F22: 0 | G22: 0 | H22: 0 | I22: =SUM(E22:H22) -> 0 | J22: =7%*I22 -> 0 | K22: =I22-J22 -> 0 | L22: INTERMEDIAÇÃO | M22: 10 | N22: 11
A23: BIANCA | B23: 15 | C23: ='GERAL 2022'!G40 -> 650 | D23: 0 | E23: =C23-D23 -> 650 | F23: 25 | G23: =D73 -> 3.9715319 | H23: =D72 -> 19.836667 | I23: =SUM(E23:H23) -> 698.8082 | J23: =7%*I23 -> 48.916574 | K23: =I23-J23 -> 649.89162 | L23: SEM DESCONTO. IPTU (4/5). SEGUROS (3/6).
A24: VANESSA | B24: 16 | C24: ='GERAL 2022'!G18 -> 640 | D24: =10%*C24 -> 64 | E24: =C24-D24 -> 576 | F24: =60 -> 60 | G24: =D77 -> 2.8368085 | H24: 0 | I24: =SUM(E24:H24) -> 638.83681 | J24: =7%*I24 -> 44.718577 | K24: =I24-J24 -> 594.11823 | L24: DESCONTO 10% (11/12). SEGURO QUITADO. IPTU (4/5). | M24: 10 | N24: 11
A25: MATEUS LEVI | B25: 17 | C25: ='GERAL 2022'!G19 -> 640 | D25: =10%*C25 -> 64 | E25: =(C25-D25) -> 576 | F25: 0 | G25: =D79 -> 2.8368085 | H25: 0 | I25: =SUM(E25:H25) -> 578.83681 | J25: =7%*I25 -> 40.518577 | K25: =I25-J25 -> 538.31823 | L25: DESCONTO 10% (10/12). SEGURO QUITADO. IPTU (4/5). | M25: 10 | N25: 11
A26: FREDSON | B26: 18 | C26: ='GERAL 2022'!G20 -> 650 | D26: =10%*C26 -> 65 | E26: =C26-D26 -> 585 | F26: =30 -> 30 | G26: =D81 -> 2.8368085 | H26: 0 | I26: =SUM(E26:H26) -> 617.83681 | J26: =7%*I26 -> 43.248577 | K26: =I26-J26 -> 574.58823 | L26: DESCONTO 10% (11/12). SEGURO QUITADO. IPTU (4/5). | M26: 10 | N26: 11
A27: ERIVANDO | B27: 19 | C27: ='GERAL 2022'!G21 -> 600 | D27: =10%*C27 -> 60 | E27: =(C27-D27) -> 540 | F27: =50 -> 50 | G27: =D83 -> 2.8368085 | H27: 0 | I27: =SUM(E27:H27) -> 592.83681 | J27: =7%*I27 -> 41.498577 | K27: =I27-J27 -> 551.33823 | L27: DESCONTO 10% (9/12). SEGURO QUITADO. IPTU (4/5). | M27: 10 | N27: 11
B28: 20 | J28: =7%*I28 -> 0
B29: 21 | J29: =7%*I29 -> 0
B30: 22 | J30: =7%*I30 -> 0
B31: 23 | J31: =7%*I31 -> 0
A32: JOÃO LEVI | B32: 24 | C32: ='GERAL 2022'!G26 -> 650 | D32: 0 | E32: =C32-D32 -> 650 | F32: 50 | G32: =D93 -> 3.9715319 | H32: =D92 -> 19.836667 | I32: =SUM(E32:H32) -> 723.8082 | J32: =7%*I32 -> 50.666574 | K32: =I32-J32 -> 673.14162 | L32: SEM DESCONTO. IPTU (4/5). SEGUROS (3/6).
A33: SHIRLEY | B33: 25 | C33: ='GERAL 2022'!G27 -> 704 | D33: =10%*C33 -> 70.4 | E33: =C33-D33 -> 633.6 | F33: =30 -> 30 | G33: =D95 -> 2.8368085 | H33: 0 | I33: =SUM(E33:H33) -> 666.43681 | J33: =7%*I33 -> 46.650577 | K33: =I33-J33 -> 619.78623 | L33: DESCONTO 10% (12/12). SEGURO QUITADO. IPTU (4/5). | M33: 10 | N33: 11
B34: 26 | J34: =7%*I34 -> 0
B35: 27
A36: TOTAL | C36: =SUM(C9:C35) -> 6824 | D36: =SUM(D9:D35) -> 323.4 | E36: =SUM(E9:E35) -> 6500.6 | F36: =SUM(F9:F35) -> 345 | G36: =SUM(G9:G35) -> 33.47434 | H36: =SUM(H9:H35) -> 118.40833 | I36: =SUM(I9:I35) -> 6997.4827 | J36: =SUM(J9:J35) -> 489.82379 | K36: =SUM(K9:K35) -> 6507.6589
A38: INADIMPLÊNCIAS
A39: NOME | B39: APTO | C39: PRINCIPAL | D39: CONDIÇÃO | I39: TOTAL | L39: OBSERVAÇÃO | M39: VENC. | N39: CARÊNCIA
A40: JOÃO PAULO | B40: 1 | C40: =4977.59-1520 -> 3457.59 | D40: R$ 4.977,59 (DÉBITO TOTAL) - R$ 1.520,00 (CAUÇÃO) | I40: =4977.59-1520 -> 3457.59 | L40: DÉBITO ATUALIZADO EM 19/02/2022 (OUT/21 A FEV/22 E MULTA), DIFERENÇA APÓS UTILIZAÇÃO DA CAUÇÃO | M40: 10 | N40: 11
A41: TOTAL | I41: =SUM(I40:I40) -> 3457.59
...

Sheet VIGÊNCIA MAIO 2022
A1: GRAND MESSEJANA II
A2: VIGÊNCIA DE MAIO 2022
A3: NOME | B3: APTO | C3: ALUGUEL | D3: DESCONTO | E3: ALUGUEL C/ DESCONTO | F3: GARAGEM | G3: IPTU | H3: SEG INC. | I3: TOTAL | J3: COMISSÃO | K3: REPASSE | L3: OBSERVAÇÃO | M3: VENC. | N3: CARÊNCIA
B4: 1
B5: 2 | J5: =7%*I5 -> 0
B6: 3 | J6: =7%*I6 -> 0
A7: AMANDA | B7: 4 | C7: ='GERAL 2022'!G16 -> 550 | D7: 0 | E7: =C7-D7 -> 550 | F7: 50 | G7: =D51 -> 2.8368085 | H7: =D50 -> 19.641667 | I7: =SUM(E7:H7) -> 622.47848 | J7: =7%*I7 -> 43.573493 | K7: =I7-J7 -> 578.90498 | L7: SEM DESCONTO. IPTU (5/5). SEGUROS (4/6). | M7: 10 | N7: 11
B8: 5 | J8: =7%*I8 -> 0
A9: LIGIA | B9: 6 | C9: ='GERAL 2022'!G8 -> 650 | D9: 0 | E9: =C9-D9 -> 650 | F9: 25 | G9: =D55 -> 3.9715319 | H9: =D54 -> 19.836667 | I9: =SUM(E9:H9) -> 698.8082 | J9: =7%*I9 -> 48.916574 | K9: =I9-J9 -> 649.89162 | L9: SEM DESCONTO. IPTU (3/5). SEGURO (3/6). | M9: 10 | N9: 11
B10: 7 | J10: =7%*I10 -> 0
A11: ARMANDO | B11: 8 | C11: ='GERAL 2022'!G10 -> 610 | D11: 0 | E11: =C11-D11 -> 610 | F11: 0 | G11: =D59 -> 2.8368085 | H11: =D58 -> 19.755 | I11: =SUM(E11:H11) -> 632.59181 | J11: =7%*I11 -> 44.281427 | K11: =I11-J11 -> 588.31038 | L11: SEM DESCONTO. IPTU (5/5). SEGUROS (4/6). | M11: 10 | N11: 11
A12: ALCIDES / RENÊ | B12: 9 | C12: ='GERAL 2022'!G11 -> 580 | D12: 0 | E12: =C12-D12 -> 580 | F12: =50 -> 50 | G12: =D61 -> 2.8368085 | H12: =D60 -> 19.696667 | I12: =SUM(E12:H12) -> 652.53348 | J12: =7%*I12 -> 45.677343 | K12: =I12-J12 -> 606.85613 | L12: SEM DESCONTO. SEGURO (5/6). IPTU (5/5). | M12: 10 | N12: 11
B13: 10
A14: JOCÉLIO | B14: 11 | C14: ='GERAL 2022'!G13 -> 550 | D14: 0 | E14: =C14-D14 -> 550 | F14: 0 | G14: =D65 -> 2.8368085 | H14: 19.81 | I14: =SUM(E14:H14) -> 572.64681 | J14: =7%*I14 -> 40.085277 | K14: =I14-J14 -> 532.56153 | L14: SEM DESCONTO. IPTU (2/5). SEGURO (2/6). | M14: 10 | N14: 11
B15: 12 | J15: =7%*I15 -> 0
A16: MARLON | B16: 13 | C16: ='GERAL 2022'!G15/31*5 -> 88.709677 | D16: 0 | E16: =C16-D16 -> 88.709677 | F16: 0 | G16: =D69/31*5 -> 0.45754976 | H16: =D68 -> 19.641667 | I16: =SUM(E16:H16) -> 108.80889 | J16: =7%*I16 -> 7.6166226 | K16: =I16-J16 -> 101.19227 | L16: PROPORCIONAL DE 05 DIAS (27/05 A 31/05). IPTU (1/5). SEGURO (1/6). | M16: 10 | N16: 11
